[WARNING] - 2022-01-25 15:13:56,313 :  * Running on all addresses.
   WARNING: This is a development server. Do not use it in a production deployment. in _internal:225
[INFO] - 2022-01-25 15:13:56,313 :  * Running on http://172.18.0.69:5000/ (Press CTRL+C to quit) in _internal:225
[INFO] - 2022-01-25 15:13:57,034 : 172.18.0.1 - - [25/Jan/2022 15:13:57] "GET / HTTP/1.1" 200 - in _internal:225
[WARNING] - 2022-02-07 08:05:03,085 :  * Running on all addresses.
   WARNING: This is a development server. Do not use it in a production deployment. in _internal:225
[INFO] - 2022-02-07 08:05:03,085 :  * Running on http://172.18.1.18:5000/ (Press CTRL+C to quit) in _internal:225
[INFO] - 2022-02-07 08:05:03,179 : 172.18.0.1 - - [07/Feb/2022 08:05:03] "GET / HTTP/1.1" 200 - in _internal:225
[WARNING] - 2022-03-16 20:34:27,173 :  * Running on all addresses.
   WARNING: This is a development server. Do not use it in a production deployment. in _internal:225
[INFO] - 2022-03-16 20:34:27,173 :  * Running on http://172.18.0.4:5000/ (Press CTRL+C to quit) in _internal:225
[INFO] - 2022-03-16 20:34:27,186 : 172.18.0.1 - - [16/Mar/2022 20:34:27] "GET / HTTP/1.1" 200 - in _internal:225
[WARNING] - 2022-03-23 08:43:54,643 :  * Running on all addresses.
   WARNING: This is a development server. Do not use it in a production deployment. in _internal:225
[INFO] - 2022-03-23 08:43:54,644 :  * Running on http://172.18.0.13:5000/ (Press CTRL+C to quit) in _internal:225
[INFO] - 2022-03-23 08:43:54,813 : 172.18.0.1 - - [23/Mar/2022 08:43:54] "GET / HTTP/1.1" 200 - in _internal:225
[INFO] - 2022-03-23 08:43:54,815 : 172.18.0.1 - - [23/Mar/2022 08:43:54] "GET / HTTP/1.1" 200 - in _internal:225
[INFO] - 2022-03-23 08:43:54,817 : 172.18.0.1 - - [23/Mar/2022 08:43:54] "GET / HTTP/1.1" 200 - in _internal:225
[INFO] - 2022-03-23 08:43:54,818 : 172.18.0.1 - - [23/Mar/2022 08:43:54] "GET / HTTP/1.1" 200 - in _internal:225
[INFO] - 2022-03-23 08:43:55,081 : 172.18.0.1 - - [23/Mar/2022 08:43:55] "GET / HTTP/1.1" 200 - in _internal:225
[INFO] - 2022-03-23 08:43:55,082 : 172.18.0.1 - - [23/Mar/2022 08:43:55] "GET / HTTP/1.1" 200 - in _internal:225
[INFO] - 2022-03-23 08:43:55,644 : 172.18.0.1 - - [23/Mar/2022 08:43:55] "GET /summary HTTP/1.1" 200 - in _internal:225
[WARNING] - 2022-03-26 13:34:36,316 :  * Running on all addresses.
   WARNING: This is a development server. Do not use it in a production deployment. in _internal:225
[INFO] - 2022-03-26 13:34:36,325 :  * Running on http://172.18.0.188:5000/ (Press CTRL+C to quit) in _internal:225
[INFO] - 2022-03-26 13:34:36,434 : 172.18.0.1 - - [26/Mar/2022 13:34:36] "GET / HTTP/1.1" 200 - in _internal:225
[WARNING] - 2022-03-27 12:42:29,598 :  * Running on all addresses.
   WARNING: This is a development server. Do not use it in a production deployment. in _internal:225
[INFO] - 2022-03-27 12:42:29,599 :  * Running on http://172.18.0.29:5000/ (Press CTRL+C to quit) in _internal:225
[INFO] - 2022-03-27 12:42:29,784 : 172.18.0.1 - - [27/Mar/2022 12:42:29] "GET / HTTP/1.1" 200 - in _internal:225
[WARNING] - 2022-03-30 10:12:27,719 :  * Running on all addresses.
   WARNING: This is a development server. Do not use it in a production deployment. in _internal:225
[INFO] - 2022-03-30 10:12:27,723 :  * Running on http://172.18.0.145:5000/ (Press CTRL+C to quit) in _internal:225
[INFO] - 2022-03-30 10:12:27,965 : 172.18.0.1 - - [30/Mar/2022 10:12:27] "GET / HTTP/1.1" 200 - in _internal:225
[INFO] - 2022-03-30 10:12:27,970 : 172.18.0.1 - - [30/Mar/2022 10:12:27] "GET / HTTP/1.1" 200 - in _internal:225
[INFO] - 2022-03-30 10:12:28,010 : 172.18.0.1 - - [30/Mar/2022 10:12:28] "[33mGET /favicon.ico HTTP/1.1[0m" 404 - in _internal:225
[INFO] - 2022-03-30 10:12:28,299 : 172.18.0.1 - - [30/Mar/2022 10:12:28] "GET / HTTP/1.1" 200 - in _internal:225
[INFO] - 2022-03-30 10:12:28,616 : 172.18.0.1 - - [30/Mar/2022 10:12:28] "[33mGET /favicon.ico HTTP/1.1[0m" 404 - in _internal:225
[WARNING] - 2023-02-09 21:42:54,745 :  * Running on all addresses.
   WARNING: This is a development server. Do not use it in a production deployment. in _internal:225
[INFO] - 2023-02-09 21:42:54,745 :  * Running on http://172.31.128.12:5000/ (Press CTRL+C to quit) in _internal:225
[INFO] - 2023-02-09 21:42:54,881 : 172.31.128.1 - - [09/Feb/2023 21:42:54] "[33mOPTIONS * HTTP/1.1[0m" 404 - in _internal:225
[INFO] - 2023-02-09 21:42:54,885 : 172.31.128.1 - - [09/Feb/2023 21:42:54] "GET / HTTP/1.1" 200 - in _internal:225
[INFO] - 2023-02-09 21:42:55,452 : 172.31.128.1 - - [09/Feb/2023 21:42:55] "[33mOPTIONS * HTTP/1.1[0m" 404 - in _internal:225
[INFO] - 2023-02-09 21:42:55,456 : 172.31.128.1 - - [09/Feb/2023 21:42:55] "GET / HTTP/1.1" 200 - in _internal:225
[INFO] - 2023-02-09 21:42:55,720 : 172.31.128.1 - - [09/Feb/2023 21:42:55] "[33mGET /favicon.ico HTTP/1.1[0m" 404 - in _internal:225
[ERROR] - 2023-02-09 21:43:25,081 : Exception on /summary [GET] in app:1457
Traceback (most recent call last):
  File "/opt/virtualenvs/python3/lib/python3.8/site-packages/flask/app.py", line 2073, in wsgi_app
    response = self.full_dispatch_request()
  File "/opt/virtualenvs/python3/lib/python3.8/site-packages/flask/app.py", line 1518, in full_dispatch_request
    rv = self.handle_user_exception(e)
  File "/opt/virtualenvs/python3/lib/python3.8/site-packages/flask/app.py", line 1516, in full_dispatch_request
    rv = self.dispatch_request()
  File "/opt/virtualenvs/python3/lib/python3.8/site-packages/flask/app.py", line 1502, in dispatch_request
    return self.ensure_sync(self.view_functions[rule.endpoint])(**req.view_args)
  File "main.py", line 36, in serve_summary
    json_template["data"]["values"] = json_data["Countries"]
KeyError: 'Countries'
[INFO] - 2023-02-09 21:43:25,082 : 172.31.128.1 - - [09/Feb/2023 21:43:25] "[35m[1mGET /summary HTTP/1.1[0m" 500 - in _internal:225
[INFO] - 2023-02-09 21:44:23,650 : 172.31.128.1 - - [09/Feb/2023 21:44:23] "GET / HTTP/1.1" 200 - in _internal:225
[INFO] - 2023-02-09 21:44:25,432 : 172.31.128.1 - - [09/Feb/2023 21:44:25] "GET / HTTP/1.1" 200 - in _internal:225
[INFO] - 2023-02-09 21:44:29,606 : 172.31.128.1 - - [09/Feb/2023 21:44:29] "GET /new HTTP/1.1" 200 - in _internal:225
[INFO] - 2023-02-09 21:44:43,369 : Serve Dutch Data in covid:50
[INFO] - 2023-02-09 21:44:43,405 : 172.31.128.1 - - [09/Feb/2023 21:44:43] "GET /netherlands HTTP/1.1" 200 - in _internal:225
[INFO] - 2023-02-09 21:44:48,563 : 172.31.128.1 - - [09/Feb/2023 21:44:48] "GET /summary HTTP/1.1" 200 - in _internal:225
[WARNING] - 2023-03-22 16:02:28,150 :  * Running on all addresses.
   WARNING: This is a development server. Do not use it in a production deployment. in _internal:225
[INFO] - 2023-03-22 16:02:28,151 :  * Running on http://172.31.128.248:5000/ (Press CTRL+C to quit) in _internal:225
[INFO] - 2023-03-22 16:02:28,800 : 172.31.128.1 - - [22/Mar/2023 16:02:28] "[33mOPTIONS * HTTP/1.1[0m" 404 - in _internal:225
[INFO] - 2023-03-22 16:02:35,865 : 172.31.128.1 - - [22/Mar/2023 16:02:35] "GET / HTTP/1.1" 200 - in _internal:225
[INFO] - 2023-03-22 16:02:36,237 : 172.31.128.1 - - [22/Mar/2023 16:02:36] "[33mGET /favicon.ico HTTP/1.1[0m" 404 - in _internal:225
[ERROR] - 2023-03-22 16:02:48,553 : Exception on /summary [GET] in app:1457
Traceback (most recent call last):
  File "/opt/virtualenvs/python3/lib/python3.8/site-packages/flask/app.py", line 2073, in wsgi_app
    response = self.full_dispatch_request()
  File "/opt/virtualenvs/python3/lib/python3.8/site-packages/flask/app.py", line 1518, in full_dispatch_request
    rv = self.handle_user_exception(e)
  File "/opt/virtualenvs/python3/lib/python3.8/site-packages/flask/app.py", line 1516, in full_dispatch_request
    rv = self.dispatch_request()
  File "/opt/virtualenvs/python3/lib/python3.8/site-packages/flask/app.py", line 1502, in dispatch_request
    return self.ensure_sync(self.view_functions[rule.endpoint])(**req.view_args)
  File "main.py", line 36, in serve_summary
    json_template["data"]["values"] = json_data["Countries"]
KeyError: 'Countries'
[INFO] - 2023-03-22 16:02:48,555 : 172.31.128.1 - - [22/Mar/2023 16:02:48] "[35m[1mGET /summary HTTP/1.1[0m" 500 - in _internal:225
[WARNING] - 2023-03-23 13:15:07,781 :  * Running on all addresses.
   WARNING: This is a development server. Do not use it in a production deployment. in _internal:225
[INFO] - 2023-03-23 13:15:07,782 :  * Running on http://172.31.128.13:5000/ (Press CTRL+C to quit) in _internal:225
[INFO] - 2023-03-23 13:24:33,514 : 172.31.128.1 - - [23/Mar/2023 13:24:33] "GET / HTTP/1.1" 200 - in _internal:225
[WARNING] - 2023-03-27 08:43:36,783 :  * Running on all addresses.
   WARNING: This is a development server. Do not use it in a production deployment. in _internal:225
[INFO] - 2023-03-27 08:43:36,784 :  * Running on http://172.31.128.13:5000/ (Press CTRL+C to quit) in _internal:225
[INFO] - 2023-03-27 08:43:36,959 : 172.31.128.1 - - [27/Mar/2023 08:43:36] "[33mOPTIONS * HTTP/1.1[0m" 404 - in _internal:225
[INFO] - 2023-03-27 08:43:37,029 : 172.31.128.1 - - [27/Mar/2023 08:43:37] "GET / HTTP/1.1" 200 - in _internal:225
[INFO] - 2023-03-27 08:43:37,070 : 172.31.128.1 - - [27/Mar/2023 08:43:37] "[33mOPTIONS * HTTP/1.1[0m" 404 - in _internal:225
[INFO] - 2023-03-27 08:43:37,153 : 172.31.128.1 - - [27/Mar/2023 08:43:37] "[33mOPTIONS * HTTP/1.1[0m" 404 - in _internal:225
[INFO] - 2023-03-27 08:43:37,210 : 172.31.128.1 - - [27/Mar/2023 08:43:37] "GET / HTTP/1.1" 200 - in _internal:225
[INFO] - 2023-03-27 08:43:37,217 : 172.31.128.1 - - [27/Mar/2023 08:43:37] "GET / HTTP/1.1" 200 - in _internal:225
[INFO] - 2023-03-27 08:43:37,834 : 172.31.128.1 - - [27/Mar/2023 08:43:37] "[33mGET /favicon.ico HTTP/1.1[0m" 404 - in _internal:225
[INFO] - 2023-03-27 08:43:44,777 : 172.31.128.1 - - [27/Mar/2023 08:43:44] "GET / HTTP/1.1" 200 - in _internal:225
[INFO] - 2023-03-27 08:43:50,789 : 172.31.128.1 - - [27/Mar/2023 08:43:50] "GET /summary HTTP/1.1" 200 - in _internal:225
[INFO] - 2023-03-29 12:17:49,272 : [31m[1mWARNING: This is a development server. Do not use it in a production deployment. Use a production WSGI server instead.[0m
 * Running on all addresses (0.0.0.0)
 * Running on http://127.0.0.1:5000
 * Running on http://172.31.128.41:5000 in _internal:224
[INFO] - 2023-03-29 12:17:49,272 : [33mPress CTRL+C to quit[0m in _internal:224
[INFO] - 2023-03-29 12:17:49,930 : 172.31.128.1 - - [29/Mar/2023 12:17:49] "GET / HTTP/1.1" 200 - in _internal:224
[INFO] - 2023-03-29 12:17:50,147 : 172.31.128.1 - - [29/Mar/2023 12:17:50] "GET / HTTP/1.1" 200 - in _internal:224
[ERROR] - 2023-03-29 12:17:57,219 : An error has occurred: HTTP status 503 in covid:32
[ERROR] - 2023-03-29 12:17:57,220 : Exception on /summary [GET] in app:1741
Traceback (most recent call last):
  File "/home/runner/Dashboard-test-git/venv/lib/python3.10/site-packages/flask/app.py", line 2525, in wsgi_app
    response = self.full_dispatch_request()
  File "/home/runner/Dashboard-test-git/venv/lib/python3.10/site-packages/flask/app.py", line 1822, in full_dispatch_request
    rv = self.handle_user_exception(e)
  File "/home/runner/Dashboard-test-git/venv/lib/python3.10/site-packages/flask/app.py", line 1820, in full_dispatch_request
    rv = self.dispatch_request()
  File "/home/runner/Dashboard-test-git/venv/lib/python3.10/site-packages/flask/app.py", line 1796, in dispatch_request
    return self.ensure_sync(self.view_functions[rule.endpoint])(**view_args)
  File "main.py", line 35, in serve_summary
    json_template["data"]["values"] = json_data["Countries"]
KeyError: 'Countries'
[INFO] - 2023-03-29 12:17:57,223 : 172.31.128.1 - - [29/Mar/2023 12:17:57] "[35m[1mGET /summary HTTP/1.1[0m" 500 - in _internal:224
[INFO] - 2023-03-29 12:18:37,100 : [31m[1mWARNING: This is a development server. Do not use it in a production deployment. Use a production WSGI server instead.[0m
 * Running on all addresses (0.0.0.0)
 * Running on http://127.0.0.1:5000
 * Running on http://172.31.128.41:5000 in _internal:224
[INFO] - 2023-03-29 12:18:37,100 : [33mPress CTRL+C to quit[0m in _internal:224
[INFO] - 2023-03-29 12:18:37,663 : 172.31.128.1 - - [29/Mar/2023 12:18:37] "GET / HTTP/1.1" 200 - in _internal:224
[INFO] - 2023-03-29 12:18:37,879 : 172.31.128.1 - - [29/Mar/2023 12:18:37] "GET / HTTP/1.1" 200 - in _internal:224
[ERROR] - 2023-03-29 12:18:41,434 : An error has occurred: HTTP status 503 in covid:32
[ERROR] - 2023-03-29 12:18:41,435 : Exception on /summary [GET] in app:1741
Traceback (most recent call last):
  File "/home/runner/Dashboard-test-git/venv/lib/python3.10/site-packages/flask/app.py", line 2525, in wsgi_app
    response = self.full_dispatch_request()
  File "/home/runner/Dashboard-test-git/venv/lib/python3.10/site-packages/flask/app.py", line 1822, in full_dispatch_request
    rv = self.handle_user_exception(e)
  File "/home/runner/Dashboard-test-git/venv/lib/python3.10/site-packages/flask/app.py", line 1820, in full_dispatch_request
    rv = self.dispatch_request()
  File "/home/runner/Dashboard-test-git/venv/lib/python3.10/site-packages/flask/app.py", line 1796, in dispatch_request
    return self.ensure_sync(self.view_functions[rule.endpoint])(**view_args)
  File "main.py", line 36, in serve_summary
    json_template["data"]["values"] = json_data["Countries"]
KeyError: 'Countries'
[INFO] - 2023-03-29 12:18:41,437 : 172.31.128.1 - - [29/Mar/2023 12:18:41] "[35m[1mGET /summary HTTP/1.1[0m" 500 - in _internal:224
[INFO] - 2023-03-29 12:26:26,982 : [31m[1mWARNING: This is a development server. Do not use it in a production deployment. Use a production WSGI server instead.[0m
 * Running on all addresses (0.0.0.0)
 * Running on http://127.0.0.1:5000
 * Running on http://172.31.128.41:5000 in _internal:224
[INFO] - 2023-03-29 12:26:26,983 : [33mPress CTRL+C to quit[0m in _internal:224
[INFO] - 2023-03-29 12:26:27,672 : 172.31.128.1 - - [29/Mar/2023 12:26:27] "GET / HTTP/1.1" 200 - in _internal:224
[INFO] - 2023-03-29 12:26:28,291 : 172.31.128.1 - - [29/Mar/2023 12:26:28] "GET / HTTP/1.1" 200 - in _internal:224
[INFO] - 2023-03-29 12:26:33,962 : 172.31.128.1 - - [29/Mar/2023 12:26:33] "GET /summary HTTP/1.1" 200 - in _internal:224
[INFO] - 2023-03-29 12:27:39,090 : [31m[1mWARNING: This is a development server. Do not use it in a production deployment. Use a production WSGI server instead.[0m
 * Running on all addresses (0.0.0.0)
 * Running on http://127.0.0.1:5000
 * Running on http://172.31.128.41:5000 in _internal:224
[INFO] - 2023-03-29 12:27:39,090 : [33mPress CTRL+C to quit[0m in _internal:224
[INFO] - 2023-03-29 12:27:39,662 : 172.31.128.1 - - [29/Mar/2023 12:27:39] "GET / HTTP/1.1" 200 - in _internal:224
[INFO] - 2023-03-29 12:27:39,880 : 172.31.128.1 - - [29/Mar/2023 12:27:39] "GET / HTTP/1.1" 200 - in _internal:224
[INFO] - 2023-03-29 12:27:45,086 : 172.31.128.1 - - [29/Mar/2023 12:27:45] "[33mGET /summart HTTP/1.1[0m" 404 - in _internal:224
[INFO] - 2023-03-29 12:27:50,060 : 172.31.128.1 - - [29/Mar/2023 12:27:50] "GET /summary HTTP/1.1" 200 - in _internal:224
[INFO] - 2023-03-29 12:33:52,992 : [31m[1mWARNING: This is a development server. Do not use it in a production deployment. Use a production WSGI server instead.[0m
 * Running on all addresses (0.0.0.0)
 * Running on http://127.0.0.1:5000
 * Running on http://172.31.128.41:5000 in _internal:224
[INFO] - 2023-03-29 12:33:52,992 : [33mPress CTRL+C to quit[0m in _internal:224
[INFO] - 2023-03-29 12:33:53,691 : 172.31.128.1 - - [29/Mar/2023 12:33:53] "GET / HTTP/1.1" 200 - in _internal:224
[INFO] - 2023-03-29 12:33:53,907 : 172.31.128.1 - - [29/Mar/2023 12:33:53] "[36mGET / HTTP/1.1[0m" 304 - in _internal:224
[INFO] - 2023-03-29 12:33:55,149 : 172.31.128.1 - - [29/Mar/2023 12:33:55] "GET /summary HTTP/1.1" 200 - in _internal:224
[INFO] - 2023-03-29 12:33:56,204 : 172.31.128.1 - - [29/Mar/2023 12:33:56] "GET /summary HTTP/1.1" 200 - in _internal:224
[INFO] - 2023-03-29 12:33:59,478 : 172.31.128.1 - - [29/Mar/2023 12:33:59] "GET / HTTP/1.1" 200 - in _internal:224
[INFO] - 2023-03-29 12:34:00,542 : 172.31.128.1 - - [29/Mar/2023 12:34:00] "GET /summary HTTP/1.1" 200 - in _internal:224
[INFO] - 2023-03-29 12:44:10,386 : [31m[1mWARNING: This is a development server. Do not use it in a production deployment. Use a production WSGI server instead.[0m
 * Running on all addresses (0.0.0.0)
 * Running on http://127.0.0.1:5000
 * Running on http://172.31.128.41:5000 in _internal:224
[INFO] - 2023-03-29 12:44:10,386 : [33mPress CTRL+C to quit[0m in _internal:224
[INFO] - 2023-03-29 12:44:10,958 : 172.31.128.1 - - [29/Mar/2023 12:44:10] "GET / HTTP/1.1" 200 - in _internal:224
[INFO] - 2023-03-29 12:44:11,175 : 172.31.128.1 - - [29/Mar/2023 12:44:11] "[36mGET / HTTP/1.1[0m" 304 - in _internal:224
[INFO] - 2023-03-29 12:44:12,160 : 172.31.128.1 - - [29/Mar/2023 12:44:12] "GET /summary HTTP/1.1" 200 - in _internal:224
[INFO] - 2023-03-29 12:44:12,906 : 172.31.128.1 - - [29/Mar/2023 12:44:12] "GET /summary HTTP/1.1" 200 - in _internal:224
[INFO] - 2023-03-29 12:44:17,858 : 172.31.128.1 - - [29/Mar/2023 12:44:17] "GET / HTTP/1.1" 200 - in _internal:224
[INFO] - 2023-03-29 12:44:18,653 : 172.31.128.1 - - [29/Mar/2023 12:44:18] "GET /summary HTTP/1.1" 200 - in _internal:224
[INFO] - 2023-03-29 12:46:53,582 : [31m[1mWARNING: This is a development server. Do not use it in a production deployment. Use a production WSGI server instead.[0m
 * Running on all addresses (0.0.0.0)
 * Running on http://127.0.0.1:5000
 * Running on http://172.31.128.41:5000 in _internal:224
[INFO] - 2023-03-29 12:46:53,583 : [33mPress CTRL+C to quit[0m in _internal:224
[INFO] - 2023-03-29 12:46:54,153 : 172.31.128.1 - - [29/Mar/2023 12:46:54] "GET / HTTP/1.1" 200 - in _internal:224
[INFO] - 2023-03-29 12:46:54,363 : 172.31.128.1 - - [29/Mar/2023 12:46:54] "[36mGET / HTTP/1.1[0m" 304 - in _internal:224
[INFO] - 2023-03-29 12:46:55,453 : 172.31.128.1 - - [29/Mar/2023 12:46:55] "GET /summary HTTP/1.1" 200 - in _internal:224
[INFO] - 2023-03-29 12:46:56,389 : 172.31.128.1 - - [29/Mar/2023 12:46:56] "GET /summary HTTP/1.1" 200 - in _internal:224
[INFO] - 2023-03-29 12:46:58,499 : 172.31.128.1 - - [29/Mar/2023 12:46:58] "GET / HTTP/1.1" 200 - in _internal:224
[INFO] - 2023-03-29 12:46:59,415 : 172.31.128.1 - - [29/Mar/2023 12:46:59] "GET /summary HTTP/1.1" 200 - in _internal:224
[INFO] - 2023-03-29 12:47:42,782 : [31m[1mWARNING: This is a development server. Do not use it in a production deployment. Use a production WSGI server instead.[0m
 * Running on all addresses (0.0.0.0)
 * Running on http://127.0.0.1:5000
 * Running on http://172.31.128.41:5000 in _internal:224
[INFO] - 2023-03-29 12:47:42,782 : [33mPress CTRL+C to quit[0m in _internal:224
[INFO] - 2023-03-29 12:47:43,373 : 172.31.128.1 - - [29/Mar/2023 12:47:43] "GET / HTTP/1.1" 200 - in _internal:224
[INFO] - 2023-03-29 12:47:43,580 : 172.31.128.1 - - [29/Mar/2023 12:47:43] "[36mGET / HTTP/1.1[0m" 304 - in _internal:224
[INFO] - 2023-03-29 12:47:44,566 : 172.31.128.1 - - [29/Mar/2023 12:47:44] "GET /summary HTTP/1.1" 200 - in _internal:224
[INFO] - 2023-03-29 12:47:45,380 : 172.31.128.1 - - [29/Mar/2023 12:47:45] "GET /summary HTTP/1.1" 200 - in _internal:224
[INFO] - 2023-03-29 12:47:47,967 : 172.31.128.1 - - [29/Mar/2023 12:47:47] "GET / HTTP/1.1" 200 - in _internal:224
[INFO] - 2023-03-29 12:47:48,864 : 172.31.128.1 - - [29/Mar/2023 12:47:48] "GET /summary HTTP/1.1" 200 - in _internal:224
[INFO] - 2023-03-29 12:48:18,900 : [31m[1mWARNING: This is a development server. Do not use it in a production deployment. Use a production WSGI server instead.[0m
 * Running on all addresses (0.0.0.0)
 * Running on http://127.0.0.1:5000
 * Running on http://172.31.128.41:5000 in _internal:224
[INFO] - 2023-03-29 12:48:18,900 : [33mPress CTRL+C to quit[0m in _internal:224
[INFO] - 2023-03-29 12:48:19,546 : 172.31.128.1 - - [29/Mar/2023 12:48:19] "GET / HTTP/1.1" 200 - in _internal:224
[INFO] - 2023-03-29 12:48:19,764 : 172.31.128.1 - - [29/Mar/2023 12:48:19] "[36mGET / HTTP/1.1[0m" 304 - in _internal:224
[INFO] - 2023-03-29 12:48:20,723 : 172.31.128.1 - - [29/Mar/2023 12:48:20] "GET /summary HTTP/1.1" 200 - in _internal:224
[INFO] - 2023-03-29 12:48:21,565 : 172.31.128.1 - - [29/Mar/2023 12:48:21] "GET /summary HTTP/1.1" 200 - in _internal:224
[INFO] - 2023-03-29 12:48:21,867 : 172.31.128.1 - - [29/Mar/2023 12:48:21] "GET / HTTP/1.1" 200 - in _internal:224
[INFO] - 2023-03-29 12:48:22,650 : 172.31.128.1 - - [29/Mar/2023 12:48:22] "GET /summary HTTP/1.1" 200 - in _internal:224
[INFO] - 2023-03-29 12:49:03,814 : [31m[1mWARNING: This is a development server. Do not use it in a production deployment. Use a production WSGI server instead.[0m
 * Running on all addresses (0.0.0.0)
 * Running on http://127.0.0.1:5000
 * Running on http://172.31.128.41:5000 in _internal:224
[INFO] - 2023-03-29 12:49:03,814 : [33mPress CTRL+C to quit[0m in _internal:224
[INFO] - 2023-03-29 12:49:04,411 : 172.31.128.1 - - [29/Mar/2023 12:49:04] "GET / HTTP/1.1" 200 - in _internal:224
[INFO] - 2023-03-29 12:49:05,028 : 172.31.128.1 - - [29/Mar/2023 12:49:05] "[36mGET / HTTP/1.1[0m" 304 - in _internal:224
[INFO] - 2023-03-29 12:49:05,630 : 172.31.128.1 - - [29/Mar/2023 12:49:05] "GET /summary HTTP/1.1" 200 - in _internal:224
[INFO] - 2023-03-29 12:49:05,920 : 172.31.128.1 - - [29/Mar/2023 12:49:05] "GET / HTTP/1.1" 200 - in _internal:224
[INFO] - 2023-03-29 12:49:06,652 : 172.31.128.1 - - [29/Mar/2023 12:49:06] "GET /summary HTTP/1.1" 200 - in _internal:224
[INFO] - 2023-03-29 12:49:06,863 : 172.31.128.1 - - [29/Mar/2023 12:49:06] "GET /summary HTTP/1.1" 200 - in _internal:224
[INFO] - 2023-03-29 12:53:08,299 : [31m[1mWARNING: This is a development server. Do not use it in a production deployment. Use a production WSGI server instead.[0m
 * Running on all addresses (0.0.0.0)
 * Running on http://127.0.0.1:5000
 * Running on http://172.31.128.41:5000 in _internal:224
[INFO] - 2023-03-29 12:53:08,299 : [33mPress CTRL+C to quit[0m in _internal:224
[INFO] - 2023-03-29 12:53:08,967 : 172.31.128.1 - - [29/Mar/2023 12:53:08] "GET / HTTP/1.1" 200 - in _internal:224
[INFO] - 2023-03-29 12:53:09,450 : 172.31.128.1 - - [29/Mar/2023 12:53:09] "[36mGET / HTTP/1.1[0m" 304 - in _internal:224
[INFO] - 2023-03-29 12:53:10,158 : 172.31.128.1 - - [29/Mar/2023 12:53:10] "GET /summary HTTP/1.1" 200 - in _internal:224
[INFO] - 2023-03-29 12:53:11,008 : 172.31.128.1 - - [29/Mar/2023 12:53:11] "GET /summary HTTP/1.1" 200 - in _internal:224
[INFO] - 2023-03-29 12:53:12,414 : 172.31.128.1 - - [29/Mar/2023 12:53:12] "GET / HTTP/1.1" 200 - in _internal:224
[INFO] - 2023-03-29 12:53:13,320 : 172.31.128.1 - - [29/Mar/2023 12:53:13] "GET /summary HTTP/1.1" 200 - in _internal:224
[INFO] - 2023-03-29 13:18:48,837 : [31m[1mWARNING: This is a development server. Do not use it in a production deployment. Use a production WSGI server instead.[0m
 * Running on all addresses (0.0.0.0)
 * Running on http://127.0.0.1:5000
 * Running on http://172.31.128.41:5000 in _internal:224
[INFO] - 2023-03-29 13:18:48,837 : [33mPress CTRL+C to quit[0m in _internal:224
[INFO] - 2023-03-29 13:18:49,512 : 172.31.128.1 - - [29/Mar/2023 13:18:49] "GET / HTTP/1.1" 200 - in _internal:224
[INFO] - 2023-03-29 13:18:49,731 : 172.31.128.1 - - [29/Mar/2023 13:18:49] "[36mGET / HTTP/1.1[0m" 304 - in _internal:224
[INFO] - 2023-03-29 13:18:50,690 : 172.31.128.1 - - [29/Mar/2023 13:18:50] "GET /summary HTTP/1.1" 200 - in _internal:224
[INFO] - 2023-03-29 13:18:51,608 : 172.31.128.1 - - [29/Mar/2023 13:18:51] "GET /summary HTTP/1.1" 200 - in _internal:224
[INFO] - 2023-03-29 13:18:53,569 : 172.31.128.1 - - [29/Mar/2023 13:18:53] "GET / HTTP/1.1" 200 - in _internal:224
[INFO] - 2023-03-29 13:18:54,411 : 172.31.128.1 - - [29/Mar/2023 13:18:54] "GET /summary HTTP/1.1" 200 - in _internal:224
[INFO] - 2023-03-29 13:24:40,803 : [31m[1mWARNING: This is a development server. Do not use it in a production deployment. Use a production WSGI server instead.[0m
 * Running on all addresses (0.0.0.0)
 * Running on http://127.0.0.1:5000
 * Running on http://172.31.128.41:5000 in _internal:224
[INFO] - 2023-03-29 13:24:40,803 : [33mPress CTRL+C to quit[0m in _internal:224
[INFO] - 2023-03-29 13:24:41,465 : 172.31.128.1 - - [29/Mar/2023 13:24:41] "GET / HTTP/1.1" 200 - in _internal:224
[INFO] - 2023-03-29 13:24:42,290 : 172.31.128.1 - - [29/Mar/2023 13:24:42] "[36mGET / HTTP/1.1[0m" 304 - in _internal:224
[ERROR] - 2023-03-29 13:24:43,586 : Exception on /netherlands [GET] in app:1741
Traceback (most recent call last):
  File "/home/runner/Dashboard-test-git/venv/lib/python3.10/site-packages/flask/app.py", line 2525, in wsgi_app
    response = self.full_dispatch_request()
  File "/home/runner/Dashboard-test-git/venv/lib/python3.10/site-packages/flask/app.py", line 1822, in full_dispatch_request
    rv = self.handle_user_exception(e)
  File "/home/runner/Dashboard-test-git/venv/lib/python3.10/site-packages/flask/app.py", line 1820, in full_dispatch_request
    rv = self.dispatch_request()
  File "/home/runner/Dashboard-test-git/venv/lib/python3.10/site-packages/flask/app.py", line 1796, in dispatch_request
    return self.ensure_sync(self.view_functions[rule.endpoint])(**view_args)
  File "main.py", line 77, in serve_netherlands_history
    json_template["data"]["values"] = json_data["data"]
KeyError: 'data'
[INFO] - 2023-03-29 13:24:43,601 : 172.31.128.1 - - [29/Mar/2023 13:24:43] "[35m[1mGET /netherlands HTTP/1.1[0m" 500 - in _internal:224
[INFO] - 2023-03-29 13:24:43,879 : 172.31.128.1 - - [29/Mar/2023 13:24:43] "GET /summary HTTP/1.1" 200 - in _internal:224
[ERROR] - 2023-03-29 13:24:44,926 : Exception on /netherlands [GET] in app:1741
Traceback (most recent call last):
  File "/home/runner/Dashboard-test-git/venv/lib/python3.10/site-packages/flask/app.py", line 2525, in wsgi_app
    response = self.full_dispatch_request()
  File "/home/runner/Dashboard-test-git/venv/lib/python3.10/site-packages/flask/app.py", line 1822, in full_dispatch_request
    rv = self.handle_user_exception(e)
  File "/home/runner/Dashboard-test-git/venv/lib/python3.10/site-packages/flask/app.py", line 1820, in full_dispatch_request
    rv = self.dispatch_request()
  File "/home/runner/Dashboard-test-git/venv/lib/python3.10/site-packages/flask/app.py", line 1796, in dispatch_request
    return self.ensure_sync(self.view_functions[rule.endpoint])(**view_args)
  File "main.py", line 77, in serve_netherlands_history
    json_template["data"]["values"] = json_data["data"]
KeyError: 'data'
[INFO] - 2023-03-29 13:24:44,999 : 172.31.128.1 - - [29/Mar/2023 13:24:44] "[35m[1mGET /netherlands HTTP/1.1[0m" 500 - in _internal:224
[ERROR] - 2023-03-29 13:24:45,408 : An error has occurred: HTTP status 429 in covid:32
[ERROR] - 2023-03-29 13:24:45,413 : Exception on /summary [GET] in app:1741
Traceback (most recent call last):
  File "/home/runner/Dashboard-test-git/venv/lib/python3.10/site-packages/flask/app.py", line 2525, in wsgi_app
    response = self.full_dispatch_request()
  File "/home/runner/Dashboard-test-git/venv/lib/python3.10/site-packages/flask/app.py", line 1822, in full_dispatch_request
    rv = self.handle_user_exception(e)
  File "/home/runner/Dashboard-test-git/venv/lib/python3.10/site-packages/flask/app.py", line 1820, in full_dispatch_request
    rv = self.dispatch_request()
  File "/home/runner/Dashboard-test-git/venv/lib/python3.10/site-packages/flask/app.py", line 1796, in dispatch_request
    return self.ensure_sync(self.view_functions[rule.endpoint])(**view_args)
  File "main.py", line 36, in serve_summary
    json_template["data"]["values"] = json_data["Countries"]
KeyError: 'Countries'
[INFO] - 2023-03-29 13:24:45,416 : 172.31.128.1 - - [29/Mar/2023 13:24:45] "[35m[1mGET /summary HTTP/1.1[0m" 500 - in _internal:224
[INFO] - 2023-03-29 13:24:55,090 : 172.31.128.1 - - [29/Mar/2023 13:24:55] "GET / HTTP/1.1" 200 - in _internal:224
[INFO] - 2023-03-29 13:24:56,013 : 172.31.128.1 - - [29/Mar/2023 13:24:56] "GET /summary HTTP/1.1" 200 - in _internal:224
[ERROR] - 2023-03-29 13:24:56,488 : Exception on /netherlands [GET] in app:1741
Traceback (most recent call last):
  File "/home/runner/Dashboard-test-git/venv/lib/python3.10/site-packages/flask/app.py", line 2525, in wsgi_app
    response = self.full_dispatch_request()
  File "/home/runner/Dashboard-test-git/venv/lib/python3.10/site-packages/flask/app.py", line 1822, in full_dispatch_request
    rv = self.handle_user_exception(e)
  File "/home/runner/Dashboard-test-git/venv/lib/python3.10/site-packages/flask/app.py", line 1820, in full_dispatch_request
    rv = self.dispatch_request()
  File "/home/runner/Dashboard-test-git/venv/lib/python3.10/site-packages/flask/app.py", line 1796, in dispatch_request
    return self.ensure_sync(self.view_functions[rule.endpoint])(**view_args)
  File "main.py", line 77, in serve_netherlands_history
    json_template["data"]["values"] = json_data["data"]
KeyError: 'data'
[INFO] - 2023-03-29 13:24:56,536 : 172.31.128.1 - - [29/Mar/2023 13:24:56] "[35m[1mGET /netherlands HTTP/1.1[0m" 500 - in _internal:224
[INFO] - 2023-03-29 13:26:06,332 : [31m[1mWARNING: This is a development server. Do not use it in a production deployment. Use a production WSGI server instead.[0m
 * Running on all addresses (0.0.0.0)
 * Running on http://127.0.0.1:5000
 * Running on http://172.31.128.41:5000 in _internal:224
[INFO] - 2023-03-29 13:26:06,333 : [33mPress CTRL+C to quit[0m in _internal:224
[INFO] - 2023-03-29 13:26:06,931 : 172.31.128.1 - - [29/Mar/2023 13:26:06] "GET / HTTP/1.1" 200 - in _internal:224
[INFO] - 2023-03-29 13:26:07,536 : 172.31.128.1 - - [29/Mar/2023 13:26:07] "[36mGET / HTTP/1.1[0m" 304 - in _internal:224
[INFO] - 2023-03-29 13:26:08,092 : 172.31.128.1 - - [29/Mar/2023 13:26:08] "GET / HTTP/1.1" 200 - in _internal:224
[INFO] - 2023-03-29 13:26:08,116 : 172.31.128.1 - - [29/Mar/2023 13:26:08] "GET /summary HTTP/1.1" 200 - in _internal:224
[ERROR] - 2023-03-29 13:26:08,186 : Exception on /netherlands [GET] in app:1741
Traceback (most recent call last):
  File "/home/runner/Dashboard-test-git/venv/lib/python3.10/site-packages/flask/app.py", line 2525, in wsgi_app
    response = self.full_dispatch_request()
  File "/home/runner/Dashboard-test-git/venv/lib/python3.10/site-packages/flask/app.py", line 1822, in full_dispatch_request
    rv = self.handle_user_exception(e)
  File "/home/runner/Dashboard-test-git/venv/lib/python3.10/site-packages/flask/app.py", line 1820, in full_dispatch_request
    rv = self.dispatch_request()
  File "/home/runner/Dashboard-test-git/venv/lib/python3.10/site-packages/flask/app.py", line 1796, in dispatch_request
    return self.ensure_sync(self.view_functions[rule.endpoint])(**view_args)
  File "main.py", line 77, in serve_netherlands_history
    json_template["data"]["values"] = json_data["data"]
KeyError: 'data'
[INFO] - 2023-03-29 13:26:08,198 : 172.31.128.1 - - [29/Mar/2023 13:26:08] "[35m[1mGET /netherlands HTTP/1.1[0m" 500 - in _internal:224
[INFO] - 2023-03-29 13:26:08,975 : 172.31.128.1 - - [29/Mar/2023 13:26:08] "GET /summary HTTP/1.1" 200 - in _internal:224
[ERROR] - 2023-03-29 13:26:09,188 : An error has occurred: HTTP status 429 in covid:32
[ERROR] - 2023-03-29 13:26:09,191 : Exception on /summary [GET] in app:1741
Traceback (most recent call last):
  File "/home/runner/Dashboard-test-git/venv/lib/python3.10/site-packages/flask/app.py", line 2525, in wsgi_app
    response = self.full_dispatch_request()
  File "/home/runner/Dashboard-test-git/venv/lib/python3.10/site-packages/flask/app.py", line 1822, in full_dispatch_request
    rv = self.handle_user_exception(e)
  File "/home/runner/Dashboard-test-git/venv/lib/python3.10/site-packages/flask/app.py", line 1820, in full_dispatch_request
    rv = self.dispatch_request()
  File "/home/runner/Dashboard-test-git/venv/lib/python3.10/site-packages/flask/app.py", line 1796, in dispatch_request
    return self.ensure_sync(self.view_functions[rule.endpoint])(**view_args)
  File "main.py", line 36, in serve_summary
    json_template["data"]["values"] = json_data["Countries"]
KeyError: 'Countries'
[INFO] - 2023-03-29 13:26:09,194 : 172.31.128.1 - - [29/Mar/2023 13:26:09] "[35m[1mGET /summary HTTP/1.1[0m" 500 - in _internal:224
[ERROR] - 2023-03-29 13:26:09,287 : An error has occurred: HTTP status 429 in covid:32
[ERROR] - 2023-03-29 13:26:09,288 : Exception on /netherlands [GET] in app:1741
Traceback (most recent call last):
  File "/home/runner/Dashboard-test-git/venv/lib/python3.10/site-packages/flask/app.py", line 2525, in wsgi_app
    response = self.full_dispatch_request()
  File "/home/runner/Dashboard-test-git/venv/lib/python3.10/site-packages/flask/app.py", line 1822, in full_dispatch_request
    rv = self.handle_user_exception(e)
  File "/home/runner/Dashboard-test-git/venv/lib/python3.10/site-packages/flask/app.py", line 1820, in full_dispatch_request
    rv = self.dispatch_request()
  File "/home/runner/Dashboard-test-git/venv/lib/python3.10/site-packages/flask/app.py", line 1796, in dispatch_request
    return self.ensure_sync(self.view_functions[rule.endpoint])(**view_args)
  File "main.py", line 77, in serve_netherlands_history
    json_template["data"]["values"] = json_data["data"]
KeyError: 'data'
[INFO] - 2023-03-29 13:26:09,289 : 172.31.128.1 - - [29/Mar/2023 13:26:09] "[35m[1mGET /netherlands HTTP/1.1[0m" 500 - in _internal:224
[ERROR] - 2023-03-29 13:26:09,386 : An error has occurred: HTTP status 429 in covid:32
[ERROR] - 2023-03-29 13:26:09,388 : Exception on /netherlands [GET] in app:1741
Traceback (most recent call last):
  File "/home/runner/Dashboard-test-git/venv/lib/python3.10/site-packages/flask/app.py", line 2525, in wsgi_app
    response = self.full_dispatch_request()
  File "/home/runner/Dashboard-test-git/venv/lib/python3.10/site-packages/flask/app.py", line 1822, in full_dispatch_request
    rv = self.handle_user_exception(e)
  File "/home/runner/Dashboard-test-git/venv/lib/python3.10/site-packages/flask/app.py", line 1820, in full_dispatch_request
    rv = self.dispatch_request()
  File "/home/runner/Dashboard-test-git/venv/lib/python3.10/site-packages/flask/app.py", line 1796, in dispatch_request
    return self.ensure_sync(self.view_functions[rule.endpoint])(**view_args)
  File "main.py", line 77, in serve_netherlands_history
    json_template["data"]["values"] = json_data["data"]
KeyError: 'data'
[INFO] - 2023-03-29 13:26:09,395 : 172.31.128.1 - - [29/Mar/2023 13:26:09] "[35m[1mGET /netherlands HTTP/1.1[0m" 500 - in _internal:224
[ERROR] - 2023-03-29 13:26:28,835 : Exception on /netherlands [GET] in app:1741
Traceback (most recent call last):
  File "/home/runner/Dashboard-test-git/venv/lib/python3.10/site-packages/flask/app.py", line 2525, in wsgi_app
    response = self.full_dispatch_request()
  File "/home/runner/Dashboard-test-git/venv/lib/python3.10/site-packages/flask/app.py", line 1822, in full_dispatch_request
    rv = self.handle_user_exception(e)
  File "/home/runner/Dashboard-test-git/venv/lib/python3.10/site-packages/flask/app.py", line 1820, in full_dispatch_request
    rv = self.dispatch_request()
  File "/home/runner/Dashboard-test-git/venv/lib/python3.10/site-packages/flask/app.py", line 1796, in dispatch_request
    return self.ensure_sync(self.view_functions[rule.endpoint])(**view_args)
  File "main.py", line 77, in serve_netherlands_history
    json_template["data"]["values"] = json_data["data"]
KeyError: 'data'
[INFO] - 2023-03-29 13:26:28,837 : 172.31.128.1 - - [29/Mar/2023 13:26:28] "[35m[1mGET /netherlands HTTP/1.1[0m" 500 - in _internal:224
[ERROR] - 2023-03-29 13:26:39,895 : Exception on /netherlands [GET] in app:1741
Traceback (most recent call last):
  File "/home/runner/Dashboard-test-git/venv/lib/python3.10/site-packages/flask/app.py", line 2525, in wsgi_app
    response = self.full_dispatch_request()
  File "/home/runner/Dashboard-test-git/venv/lib/python3.10/site-packages/flask/app.py", line 1822, in full_dispatch_request
    rv = self.handle_user_exception(e)
  File "/home/runner/Dashboard-test-git/venv/lib/python3.10/site-packages/flask/app.py", line 1820, in full_dispatch_request
    rv = self.dispatch_request()
  File "/home/runner/Dashboard-test-git/venv/lib/python3.10/site-packages/flask/app.py", line 1796, in dispatch_request
    return self.ensure_sync(self.view_functions[rule.endpoint])(**view_args)
  File "main.py", line 77, in serve_netherlands_history
    json_template["data"]["values"] = json_data["data"]
KeyError: 'data'
[INFO] - 2023-03-29 13:26:39,896 : 172.31.128.1 - - [29/Mar/2023 13:26:39] "[35m[1mGET /netherlands HTTP/1.1[0m" 500 - in _internal:224
[INFO] - 2023-03-29 13:27:24,979 : 172.31.128.1 - - [29/Mar/2023 13:27:24] "[36mGET / HTTP/1.1[0m" 304 - in _internal:224
[INFO] - 2023-03-29 13:27:26,609 : 172.31.128.1 - - [29/Mar/2023 13:27:26] "GET /summary HTTP/1.1" 200 - in _internal:224
[ERROR] - 2023-03-29 13:27:26,679 : Exception on /netherlands [GET] in app:1741
Traceback (most recent call last):
  File "/home/runner/Dashboard-test-git/venv/lib/python3.10/site-packages/flask/app.py", line 2525, in wsgi_app
    response = self.full_dispatch_request()
  File "/home/runner/Dashboard-test-git/venv/lib/python3.10/site-packages/flask/app.py", line 1822, in full_dispatch_request
    rv = self.handle_user_exception(e)
  File "/home/runner/Dashboard-test-git/venv/lib/python3.10/site-packages/flask/app.py", line 1820, in full_dispatch_request
    rv = self.dispatch_request()
  File "/home/runner/Dashboard-test-git/venv/lib/python3.10/site-packages/flask/app.py", line 1796, in dispatch_request
    return self.ensure_sync(self.view_functions[rule.endpoint])(**view_args)
  File "main.py", line 77, in serve_netherlands_history
    json_template["data"]["values"] = json_data["data"]
KeyError: 'data'
[INFO] - 2023-03-29 13:27:26,766 : 172.31.128.1 - - [29/Mar/2023 13:27:26] "[35m[1mGET /netherlands HTTP/1.1[0m" 500 - in _internal:224
[INFO] - 2023-03-29 13:27:34,669 : [31m[1mWARNING: This is a development server. Do not use it in a production deployment. Use a production WSGI server instead.[0m
 * Running on all addresses (0.0.0.0)
 * Running on http://127.0.0.1:5000
 * Running on http://172.31.128.41:5000 in _internal:224
[INFO] - 2023-03-29 13:27:34,669 : [33mPress CTRL+C to quit[0m in _internal:224
[INFO] - 2023-03-29 13:27:35,270 : 172.31.128.1 - - [29/Mar/2023 13:27:35] "[36mGET / HTTP/1.1[0m" 304 - in _internal:224
[INFO] - 2023-03-29 13:27:35,883 : 172.31.128.1 - - [29/Mar/2023 13:27:35] "[36mGET / HTTP/1.1[0m" 304 - in _internal:224
[INFO] - 2023-03-29 13:27:36,484 : 172.31.128.1 - - [29/Mar/2023 13:27:36] "GET /summary HTTP/1.1" 200 - in _internal:224
[INFO] - 2023-03-29 13:27:37,391 : 172.31.128.1 - - [29/Mar/2023 13:27:37] "GET /summary HTTP/1.1" 200 - in _internal:224
[INFO] - 2023-03-29 13:27:40,024 : Serve Dutch Data in covid:50
[INFO] - 2023-03-29 13:27:40,120 : 172.31.128.1 - - [29/Mar/2023 13:27:40] "GET /netherlands HTTP/1.1" 200 - in _internal:224
[INFO] - 2023-03-29 13:27:40,250 : 172.31.128.1 - - [29/Mar/2023 13:27:40] "[36mGET / HTTP/1.1[0m" 304 - in _internal:224
[ERROR] - 2023-03-29 13:27:40,930 : An error has occurred: HTTP status 429 in covid:55
[ERROR] - 2023-03-29 13:27:40,931 : Exception on /netherlands [GET] in app:1741
Traceback (most recent call last):
  File "/home/runner/Dashboard-test-git/venv/lib/python3.10/site-packages/flask/app.py", line 2525, in wsgi_app
    response = self.full_dispatch_request()
  File "/home/runner/Dashboard-test-git/venv/lib/python3.10/site-packages/flask/app.py", line 1822, in full_dispatch_request
    rv = self.handle_user_exception(e)
  File "/home/runner/Dashboard-test-git/venv/lib/python3.10/site-packages/flask/app.py", line 1820, in full_dispatch_request
    rv = self.dispatch_request()
  File "/home/runner/Dashboard-test-git/venv/lib/python3.10/site-packages/flask/app.py", line 1796, in dispatch_request
    return self.ensure_sync(self.view_functions[rule.endpoint])(**view_args)
  File "main.py", line 77, in serve_netherlands_history
    json_template["data"]["values"] = json_data["data"]
KeyError: 'data'
[INFO] - 2023-03-29 13:27:40,934 : 172.31.128.1 - - [29/Mar/2023 13:27:40] "[35m[1mGET /netherlands HTTP/1.1[0m" 500 - in _internal:224
[ERROR] - 2023-03-29 13:27:41,070 : An error has occurred: HTTP status 429 in covid:32
[ERROR] - 2023-03-29 13:27:41,071 : Exception on /summary [GET] in app:1741
Traceback (most recent call last):
  File "/home/runner/Dashboard-test-git/venv/lib/python3.10/site-packages/flask/app.py", line 2525, in wsgi_app
    response = self.full_dispatch_request()
  File "/home/runner/Dashboard-test-git/venv/lib/python3.10/site-packages/flask/app.py", line 1822, in full_dispatch_request
    rv = self.handle_user_exception(e)
  File "/home/runner/Dashboard-test-git/venv/lib/python3.10/site-packages/flask/app.py", line 1820, in full_dispatch_request
    rv = self.dispatch_request()
  File "/home/runner/Dashboard-test-git/venv/lib/python3.10/site-packages/flask/app.py", line 1796, in dispatch_request
    return self.ensure_sync(self.view_functions[rule.endpoint])(**view_args)
  File "main.py", line 36, in serve_summary
    json_template["data"]["values"] = json_data["Countries"]
KeyError: 'Countries'
[INFO] - 2023-03-29 13:27:41,073 : 172.31.128.1 - - [29/Mar/2023 13:27:41] "[35m[1mGET /summary HTTP/1.1[0m" 500 - in _internal:224
[ERROR] - 2023-03-29 13:27:41,374 : An error has occurred: HTTP status 429 in covid:55
[ERROR] - 2023-03-29 13:27:41,376 : Exception on /netherlands [GET] in app:1741
Traceback (most recent call last):
  File "/home/runner/Dashboard-test-git/venv/lib/python3.10/site-packages/flask/app.py", line 2525, in wsgi_app
    response = self.full_dispatch_request()
  File "/home/runner/Dashboard-test-git/venv/lib/python3.10/site-packages/flask/app.py", line 1822, in full_dispatch_request
    rv = self.handle_user_exception(e)
  File "/home/runner/Dashboard-test-git/venv/lib/python3.10/site-packages/flask/app.py", line 1820, in full_dispatch_request
    rv = self.dispatch_request()
  File "/home/runner/Dashboard-test-git/venv/lib/python3.10/site-packages/flask/app.py", line 1796, in dispatch_request
    return self.ensure_sync(self.view_functions[rule.endpoint])(**view_args)
  File "main.py", line 77, in serve_netherlands_history
    json_template["data"]["values"] = json_data["data"]
KeyError: 'data'
[INFO] - 2023-03-29 13:27:41,378 : 172.31.128.1 - - [29/Mar/2023 13:27:41] "[35m[1mGET /netherlands HTTP/1.1[0m" 500 - in _internal:224
[INFO] - 2023-03-29 13:27:49,392 : Serve Dutch Data in covid:50
[INFO] - 2023-03-29 13:27:49,669 : 172.31.128.1 - - [29/Mar/2023 13:27:49] "GET /netherlands HTTP/1.1" 200 - in _internal:224
[INFO] - 2023-03-29 13:28:46,172 : [31m[1mWARNING: This is a development server. Do not use it in a production deployment. Use a production WSGI server instead.[0m
 * Running on all addresses (0.0.0.0)
 * Running on http://127.0.0.1:5000
 * Running on http://172.31.128.41:5000 in _internal:224
[INFO] - 2023-03-29 13:28:46,172 : [33mPress CTRL+C to quit[0m in _internal:224
[INFO] - 2023-03-29 13:28:46,774 : 172.31.128.1 - - [29/Mar/2023 13:28:46] "GET / HTTP/1.1" 200 - in _internal:224
[ERROR] - 2023-03-29 13:28:47,318 : Exception on /new [GET] in app:1741
Traceback (most recent call last):
  File "/home/runner/Dashboard-test-git/venv/lib/python3.10/site-packages/flask/app.py", line 2525, in wsgi_app
    response = self.full_dispatch_request()
  File "/home/runner/Dashboard-test-git/venv/lib/python3.10/site-packages/flask/app.py", line 1822, in full_dispatch_request
    rv = self.handle_user_exception(e)
  File "/home/runner/Dashboard-test-git/venv/lib/python3.10/site-packages/flask/app.py", line 1820, in full_dispatch_request
    rv = self.dispatch_request()
  File "/home/runner/Dashboard-test-git/venv/lib/python3.10/site-packages/flask/app.py", line 1796, in dispatch_request
    return self.ensure_sync(self.view_functions[rule.endpoint])(**view_args)
  File "main.py", line 48, in serve_summary_new
    json_template = json.load(open("templates/new.json"))
FileNotFoundError: [Errno 2] No such file or directory: 'templates/new.json'
[INFO] - 2023-03-29 13:28:47,349 : 172.31.128.1 - - [29/Mar/2023 13:28:47] "[35m[1mGET /new HTTP/1.1[0m" 500 - in _internal:224
[INFO] - 2023-03-29 13:28:47,468 : 172.31.128.1 - - [29/Mar/2023 13:28:47] "[36mGET / HTTP/1.1[0m" 304 - in _internal:224
[ERROR] - 2023-03-29 13:28:47,968 : Exception on /new [GET] in app:1741
Traceback (most recent call last):
  File "/home/runner/Dashboard-test-git/venv/lib/python3.10/site-packages/flask/app.py", line 2525, in wsgi_app
    response = self.full_dispatch_request()
  File "/home/runner/Dashboard-test-git/venv/lib/python3.10/site-packages/flask/app.py", line 1822, in full_dispatch_request
    rv = self.handle_user_exception(e)
  File "/home/runner/Dashboard-test-git/venv/lib/python3.10/site-packages/flask/app.py", line 1820, in full_dispatch_request
    rv = self.dispatch_request()
  File "/home/runner/Dashboard-test-git/venv/lib/python3.10/site-packages/flask/app.py", line 1796, in dispatch_request
    return self.ensure_sync(self.view_functions[rule.endpoint])(**view_args)
  File "main.py", line 48, in serve_summary_new
    json_template = json.load(open("templates/new.json"))
FileNotFoundError: [Errno 2] No such file or directory: 'templates/new.json'
[INFO] - 2023-03-29 13:28:47,969 : 172.31.128.1 - - [29/Mar/2023 13:28:47] "[35m[1mGET /new HTTP/1.1[0m" 500 - in _internal:224
[INFO] - 2023-03-29 13:28:48,077 : 172.31.128.1 - - [29/Mar/2023 13:28:48] "GET /summary HTTP/1.1" 200 - in _internal:224
[INFO] - 2023-03-29 13:28:48,295 : Serve Dutch Data in covid:50
[INFO] - 2023-03-29 13:28:48,509 : 172.31.128.1 - - [29/Mar/2023 13:28:48] "GET /netherlands HTTP/1.1" 200 - in _internal:224
[INFO] - 2023-03-29 13:28:49,180 : 172.31.128.1 - - [29/Mar/2023 13:28:49] "GET /summary HTTP/1.1" 200 - in _internal:224
[ERROR] - 2023-03-29 13:28:49,380 : An error has occurred: HTTP status 429 in covid:55
[ERROR] - 2023-03-29 13:28:49,381 : Exception on /netherlands [GET] in app:1741
Traceback (most recent call last):
  File "/home/runner/Dashboard-test-git/venv/lib/python3.10/site-packages/flask/app.py", line 2525, in wsgi_app
    response = self.full_dispatch_request()
  File "/home/runner/Dashboard-test-git/venv/lib/python3.10/site-packages/flask/app.py", line 1822, in full_dispatch_request
    rv = self.handle_user_exception(e)
  File "/home/runner/Dashboard-test-git/venv/lib/python3.10/site-packages/flask/app.py", line 1820, in full_dispatch_request
    rv = self.dispatch_request()
  File "/home/runner/Dashboard-test-git/venv/lib/python3.10/site-packages/flask/app.py", line 1796, in dispatch_request
    return self.ensure_sync(self.view_functions[rule.endpoint])(**view_args)
  File "main.py", line 77, in serve_netherlands_history
    json_template["data"]["values"] = json_data["data"]
KeyError: 'data'
[INFO] - 2023-03-29 13:28:49,383 : 172.31.128.1 - - [29/Mar/2023 13:28:49] "[35m[1mGET /netherlands HTTP/1.1[0m" 500 - in _internal:224
[INFO] - 2023-03-29 13:28:51,051 : 172.31.128.1 - - [29/Mar/2023 13:28:51] "GET / HTTP/1.1" 200 - in _internal:224
[ERROR] - 2023-03-29 13:28:51,332 : Exception on /new [GET] in app:1741
Traceback (most recent call last):
  File "/home/runner/Dashboard-test-git/venv/lib/python3.10/site-packages/flask/app.py", line 2525, in wsgi_app
    response = self.full_dispatch_request()
  File "/home/runner/Dashboard-test-git/venv/lib/python3.10/site-packages/flask/app.py", line 1822, in full_dispatch_request
    rv = self.handle_user_exception(e)
  File "/home/runner/Dashboard-test-git/venv/lib/python3.10/site-packages/flask/app.py", line 1820, in full_dispatch_request
    rv = self.dispatch_request()
  File "/home/runner/Dashboard-test-git/venv/lib/python3.10/site-packages/flask/app.py", line 1796, in dispatch_request
    return self.ensure_sync(self.view_functions[rule.endpoint])(**view_args)
  File "main.py", line 48, in serve_summary_new
    json_template = json.load(open("templates/new.json"))
FileNotFoundError: [Errno 2] No such file or directory: 'templates/new.json'
[INFO] - 2023-03-29 13:28:51,335 : 172.31.128.1 - - [29/Mar/2023 13:28:51] "[35m[1mGET /new HTTP/1.1[0m" 500 - in _internal:224
[ERROR] - 2023-03-29 13:28:51,890 : An error has occurred: HTTP status 429 in covid:32
[ERROR] - 2023-03-29 13:28:51,892 : Exception on /summary [GET] in app:1741
Traceback (most recent call last):
  File "/home/runner/Dashboard-test-git/venv/lib/python3.10/site-packages/flask/app.py", line 2525, in wsgi_app
    response = self.full_dispatch_request()
  File "/home/runner/Dashboard-test-git/venv/lib/python3.10/site-packages/flask/app.py", line 1822, in full_dispatch_request
    rv = self.handle_user_exception(e)
  File "/home/runner/Dashboard-test-git/venv/lib/python3.10/site-packages/flask/app.py", line 1820, in full_dispatch_request
    rv = self.dispatch_request()
  File "/home/runner/Dashboard-test-git/venv/lib/python3.10/site-packages/flask/app.py", line 1796, in dispatch_request
    return self.ensure_sync(self.view_functions[rule.endpoint])(**view_args)
  File "main.py", line 36, in serve_summary
    json_template["data"]["values"] = json_data["Countries"]
KeyError: 'Countries'
[INFO] - 2023-03-29 13:28:51,894 : 172.31.128.1 - - [29/Mar/2023 13:28:51] "[35m[1mGET /summary HTTP/1.1[0m" 500 - in _internal:224
[ERROR] - 2023-03-29 13:28:51,969 : An error has occurred: HTTP status 429 in covid:55
[ERROR] - 2023-03-29 13:28:51,970 : Exception on /netherlands [GET] in app:1741
Traceback (most recent call last):
  File "/home/runner/Dashboard-test-git/venv/lib/python3.10/site-packages/flask/app.py", line 2525, in wsgi_app
    response = self.full_dispatch_request()
  File "/home/runner/Dashboard-test-git/venv/lib/python3.10/site-packages/flask/app.py", line 1822, in full_dispatch_request
    rv = self.handle_user_exception(e)
  File "/home/runner/Dashboard-test-git/venv/lib/python3.10/site-packages/flask/app.py", line 1820, in full_dispatch_request
    rv = self.dispatch_request()
  File "/home/runner/Dashboard-test-git/venv/lib/python3.10/site-packages/flask/app.py", line 1796, in dispatch_request
    return self.ensure_sync(self.view_functions[rule.endpoint])(**view_args)
  File "main.py", line 77, in serve_netherlands_history
    json_template["data"]["values"] = json_data["data"]
KeyError: 'data'
[INFO] - 2023-03-29 13:28:51,975 : 172.31.128.1 - - [29/Mar/2023 13:28:51] "[35m[1mGET /netherlands HTTP/1.1[0m" 500 - in _internal:224
[INFO] - 2023-03-29 13:30:35,020 : [31m[1mWARNING: This is a development server. Do not use it in a production deployment. Use a production WSGI server instead.[0m
 * Running on all addresses (0.0.0.0)
 * Running on http://127.0.0.1:5000
 * Running on http://172.31.128.41:5000 in _internal:224
[INFO] - 2023-03-29 13:30:35,021 : [33mPress CTRL+C to quit[0m in _internal:224
[INFO] - 2023-03-29 13:30:35,824 : 172.31.128.1 - - [29/Mar/2023 13:30:35] "GET / HTTP/1.1" 200 - in _internal:224
[INFO] - 2023-03-29 13:30:36,629 : 172.31.128.1 - - [29/Mar/2023 13:30:36] "[36mGET / HTTP/1.1[0m" 304 - in _internal:224
[INFO] - 2023-03-29 13:30:37,551 : 172.31.128.1 - - [29/Mar/2023 13:30:37] "GET /new HTTP/1.1" 200 - in _internal:224
[INFO] - 2023-03-29 13:30:37,563 : 172.31.128.1 - - [29/Mar/2023 13:30:37] "GET /summary HTTP/1.1" 200 - in _internal:224
[INFO] - 2023-03-29 13:30:37,775 : Serve Dutch Data in covid:50
[INFO] - 2023-03-29 13:30:37,979 : 172.31.128.1 - - [29/Mar/2023 13:30:37] "GET /netherlands HTTP/1.1" 200 - in _internal:224
[ERROR] - 2023-03-29 13:30:38,683 : An error has occurred: HTTP status 429 in covid:32
[ERROR] - 2023-03-29 13:30:38,686 : Exception on /summary [GET] in app:1741
Traceback (most recent call last):
  File "/home/runner/Dashboard-test-git/venv/lib/python3.10/site-packages/flask/app.py", line 2525, in wsgi_app
    response = self.full_dispatch_request()
  File "/home/runner/Dashboard-test-git/venv/lib/python3.10/site-packages/flask/app.py", line 1822, in full_dispatch_request
    rv = self.handle_user_exception(e)
  File "/home/runner/Dashboard-test-git/venv/lib/python3.10/site-packages/flask/app.py", line 1820, in full_dispatch_request
    rv = self.dispatch_request()
  File "/home/runner/Dashboard-test-git/venv/lib/python3.10/site-packages/flask/app.py", line 1796, in dispatch_request
    return self.ensure_sync(self.view_functions[rule.endpoint])(**view_args)
  File "main.py", line 36, in serve_summary
    json_template["data"]["values"] = json_data["Countries"]
KeyError: 'Countries'
[INFO] - 2023-03-29 13:30:38,698 : 172.31.128.1 - - [29/Mar/2023 13:30:38] "[35m[1mGET /summary HTTP/1.1[0m" 500 - in _internal:224
[ERROR] - 2023-03-29 13:30:39,128 : An error has occurred: HTTP status 429 in covid:32
[ERROR] - 2023-03-29 13:30:39,129 : Exception on /new [GET] in app:1741
Traceback (most recent call last):
  File "/home/runner/Dashboard-test-git/venv/lib/python3.10/site-packages/flask/app.py", line 2525, in wsgi_app
    response = self.full_dispatch_request()
  File "/home/runner/Dashboard-test-git/venv/lib/python3.10/site-packages/flask/app.py", line 1822, in full_dispatch_request
    rv = self.handle_user_exception(e)
  File "/home/runner/Dashboard-test-git/venv/lib/python3.10/site-packages/flask/app.py", line 1820, in full_dispatch_request
    rv = self.dispatch_request()
  File "/home/runner/Dashboard-test-git/venv/lib/python3.10/site-packages/flask/app.py", line 1796, in dispatch_request
    return self.ensure_sync(self.view_functions[rule.endpoint])(**view_args)
  File "main.py", line 54, in serve_summary_new
    for key in json_data["Global"]:
KeyError: 'Global'
[INFO] - 2023-03-29 13:30:39,179 : 172.31.128.1 - - [29/Mar/2023 13:30:39] "[35m[1mGET /new HTTP/1.1[0m" 500 - in _internal:224
[ERROR] - 2023-03-29 13:30:39,200 : An error has occurred: HTTP status 429 in covid:55
[ERROR] - 2023-03-29 13:30:39,201 : Exception on /netherlands [GET] in app:1741
Traceback (most recent call last):
  File "/home/runner/Dashboard-test-git/venv/lib/python3.10/site-packages/flask/app.py", line 2525, in wsgi_app
    response = self.full_dispatch_request()
  File "/home/runner/Dashboard-test-git/venv/lib/python3.10/site-packages/flask/app.py", line 1822, in full_dispatch_request
    rv = self.handle_user_exception(e)
  File "/home/runner/Dashboard-test-git/venv/lib/python3.10/site-packages/flask/app.py", line 1820, in full_dispatch_request
    rv = self.dispatch_request()
  File "/home/runner/Dashboard-test-git/venv/lib/python3.10/site-packages/flask/app.py", line 1796, in dispatch_request
    return self.ensure_sync(self.view_functions[rule.endpoint])(**view_args)
  File "main.py", line 77, in serve_netherlands_history
    json_template["data"]["values"] = json_data["data"]
KeyError: 'data'
[INFO] - 2023-03-29 13:30:39,203 : 172.31.128.1 - - [29/Mar/2023 13:30:39] "[35m[1mGET /netherlands HTTP/1.1[0m" 500 - in _internal:224
[ERROR] - 2023-03-29 13:30:40,073 : An error has occurred: HTTP status 429 in covid:32
[ERROR] - 2023-03-29 13:30:40,083 : Exception on /new [GET] in app:1741
Traceback (most recent call last):
  File "/home/runner/Dashboard-test-git/venv/lib/python3.10/site-packages/flask/app.py", line 2525, in wsgi_app
    response = self.full_dispatch_request()
  File "/home/runner/Dashboard-test-git/venv/lib/python3.10/site-packages/flask/app.py", line 1822, in full_dispatch_request
    rv = self.handle_user_exception(e)
  File "/home/runner/Dashboard-test-git/venv/lib/python3.10/site-packages/flask/app.py", line 1820, in full_dispatch_request
    rv = self.dispatch_request()
  File "/home/runner/Dashboard-test-git/venv/lib/python3.10/site-packages/flask/app.py", line 1796, in dispatch_request
    return self.ensure_sync(self.view_functions[rule.endpoint])(**view_args)
  File "main.py", line 54, in serve_summary_new
    for key in json_data["Global"]:
KeyError: 'Global'
[INFO] - 2023-03-29 13:30:40,087 : 172.31.128.1 - - [29/Mar/2023 13:30:40] "[35m[1mGET /new HTTP/1.1[0m" 500 - in _internal:224
[INFO] - 2023-03-29 13:30:40,453 : 172.31.128.1 - - [29/Mar/2023 13:30:40] "GET / HTTP/1.1" 200 - in _internal:224
[ERROR] - 2023-03-29 13:30:41,085 : An error has occurred: HTTP status 429 in covid:32
[ERROR] - 2023-03-29 13:30:41,090 : Exception on /new [GET] in app:1741
Traceback (most recent call last):
  File "/home/runner/Dashboard-test-git/venv/lib/python3.10/site-packages/flask/app.py", line 2525, in wsgi_app
    response = self.full_dispatch_request()
  File "/home/runner/Dashboard-test-git/venv/lib/python3.10/site-packages/flask/app.py", line 1822, in full_dispatch_request
    rv = self.handle_user_exception(e)
  File "/home/runner/Dashboard-test-git/venv/lib/python3.10/site-packages/flask/app.py", line 1820, in full_dispatch_request
    rv = self.dispatch_request()
  File "/home/runner/Dashboard-test-git/venv/lib/python3.10/site-packages/flask/app.py", line 1796, in dispatch_request
    return self.ensure_sync(self.view_functions[rule.endpoint])(**view_args)
  File "main.py", line 54, in serve_summary_new
    for key in json_data["Global"]:
KeyError: 'Global'
[INFO] - 2023-03-29 13:30:41,167 : 172.31.128.1 - - [29/Mar/2023 13:30:41] "[35m[1mGET /new HTTP/1.1[0m" 500 - in _internal:224
[ERROR] - 2023-03-29 13:30:41,624 : An error has occurred: HTTP status 429 in covid:32
[ERROR] - 2023-03-29 13:30:41,667 : Exception on /new [GET] in app:1741
Traceback (most recent call last):
  File "/home/runner/Dashboard-test-git/venv/lib/python3.10/site-packages/flask/app.py", line 2525, in wsgi_app
    response = self.full_dispatch_request()
  File "/home/runner/Dashboard-test-git/venv/lib/python3.10/site-packages/flask/app.py", line 1822, in full_dispatch_request
    rv = self.handle_user_exception(e)
  File "/home/runner/Dashboard-test-git/venv/lib/python3.10/site-packages/flask/app.py", line 1820, in full_dispatch_request
    rv = self.dispatch_request()
  File "/home/runner/Dashboard-test-git/venv/lib/python3.10/site-packages/flask/app.py", line 1796, in dispatch_request
    return self.ensure_sync(self.view_functions[rule.endpoint])(**view_args)
  File "main.py", line 54, in serve_summary_new
    for key in json_data["Global"]:
KeyError: 'Global'
[INFO] - 2023-03-29 13:30:41,669 : 172.31.128.1 - - [29/Mar/2023 13:30:41] "[35m[1mGET /new HTTP/1.1[0m" 500 - in _internal:224
[ERROR] - 2023-03-29 13:30:41,696 : An error has occurred: HTTP status 429 in covid:55
[ERROR] - 2023-03-29 13:30:41,725 : Exception on /netherlands [GET] in app:1741
Traceback (most recent call last):
  File "/home/runner/Dashboard-test-git/venv/lib/python3.10/site-packages/flask/app.py", line 2525, in wsgi_app
    response = self.full_dispatch_request()
  File "/home/runner/Dashboard-test-git/venv/lib/python3.10/site-packages/flask/app.py", line 1822, in full_dispatch_request
    rv = self.handle_user_exception(e)
  File "/home/runner/Dashboard-test-git/venv/lib/python3.10/site-packages/flask/app.py", line 1820, in full_dispatch_request
    rv = self.dispatch_request()
  File "/home/runner/Dashboard-test-git/venv/lib/python3.10/site-packages/flask/app.py", line 1796, in dispatch_request
    return self.ensure_sync(self.view_functions[rule.endpoint])(**view_args)
  File "main.py", line 77, in serve_netherlands_history
    json_template["data"]["values"] = json_data["data"]
KeyError: 'data'
[INFO] - 2023-03-29 13:30:41,728 : 172.31.128.1 - - [29/Mar/2023 13:30:41] "[35m[1mGET /netherlands HTTP/1.1[0m" 500 - in _internal:224
[ERROR] - 2023-03-29 13:30:41,787 : An error has occurred: HTTP status 429 in covid:32
[ERROR] - 2023-03-29 13:30:41,793 : Exception on /summary [GET] in app:1741
Traceback (most recent call last):
  File "/home/runner/Dashboard-test-git/venv/lib/python3.10/site-packages/flask/app.py", line 2525, in wsgi_app
    response = self.full_dispatch_request()
  File "/home/runner/Dashboard-test-git/venv/lib/python3.10/site-packages/flask/app.py", line 1822, in full_dispatch_request
    rv = self.handle_user_exception(e)
  File "/home/runner/Dashboard-test-git/venv/lib/python3.10/site-packages/flask/app.py", line 1820, in full_dispatch_request
    rv = self.dispatch_request()
  File "/home/runner/Dashboard-test-git/venv/lib/python3.10/site-packages/flask/app.py", line 1796, in dispatch_request
    return self.ensure_sync(self.view_functions[rule.endpoint])(**view_args)
  File "main.py", line 36, in serve_summary
    json_template["data"]["values"] = json_data["Countries"]
KeyError: 'Countries'
[INFO] - 2023-03-29 13:30:41,795 : 172.31.128.1 - - [29/Mar/2023 13:30:41] "[35m[1mGET /summary HTTP/1.1[0m" 500 - in _internal:224
[INFO] - 2023-03-29 13:30:42,726 : 172.31.128.1 - - [29/Mar/2023 13:30:42] "GET /new HTTP/1.1" 200 - in _internal:224
[INFO] - 2023-03-29 13:30:50,075 : Serve Dutch Data in covid:50
[INFO] - 2023-03-29 13:30:50,239 : 172.31.128.1 - - [29/Mar/2023 13:30:50] "GET /netherlands HTTP/1.1" 200 - in _internal:224
[INFO] - 2023-03-29 13:30:56,346 : 172.31.128.1 - - [29/Mar/2023 13:30:56] "GET /new HTTP/1.1" 200 - in _internal:224
[INFO] - 2023-03-29 13:31:01,902 : 172.31.128.1 - - [29/Mar/2023 13:31:01] "GET /summary HTTP/1.1" 200 - in _internal:224
[INFO] - 2023-03-29 13:31:06,760 : 172.31.128.1 - - [29/Mar/2023 13:31:06] "[36mGET / HTTP/1.1[0m" 304 - in _internal:224
[INFO] - 2023-03-29 13:31:07,704 : 172.31.128.1 - - [29/Mar/2023 13:31:07] "GET /new HTTP/1.1" 200 - in _internal:224
[INFO] - 2023-03-29 13:31:07,791 : 172.31.128.1 - - [29/Mar/2023 13:31:07] "GET /summary HTTP/1.1" 200 - in _internal:224
[INFO] - 2023-03-29 13:31:07,912 : Serve Dutch Data in covid:50
[INFO] - 2023-03-29 13:31:08,199 : 172.31.128.1 - - [29/Mar/2023 13:31:08] "GET /netherlands HTTP/1.1" 200 - in _internal:224
[ERROR] - 2023-03-29 13:31:08,766 : An error has occurred: HTTP status 429 in covid:32
[ERROR] - 2023-03-29 13:31:08,767 : Exception on /new [GET] in app:1741
Traceback (most recent call last):
  File "/home/runner/Dashboard-test-git/venv/lib/python3.10/site-packages/flask/app.py", line 2525, in wsgi_app
    response = self.full_dispatch_request()
  File "/home/runner/Dashboard-test-git/venv/lib/python3.10/site-packages/flask/app.py", line 1822, in full_dispatch_request
    rv = self.handle_user_exception(e)
  File "/home/runner/Dashboard-test-git/venv/lib/python3.10/site-packages/flask/app.py", line 1820, in full_dispatch_request
    rv = self.dispatch_request()
  File "/home/runner/Dashboard-test-git/venv/lib/python3.10/site-packages/flask/app.py", line 1796, in dispatch_request
    return self.ensure_sync(self.view_functions[rule.endpoint])(**view_args)
  File "main.py", line 54, in serve_summary_new
    for key in json_data["Global"]:
KeyError: 'Global'
[INFO] - 2023-03-29 13:31:08,768 : 172.31.128.1 - - [29/Mar/2023 13:31:08] "[35m[1mGET /new HTTP/1.1[0m" 500 - in _internal:224
[INFO] - 2023-03-29 13:32:22,598 : [31m[1mWARNING: This is a development server. Do not use it in a production deployment. Use a production WSGI server instead.[0m
 * Running on all addresses (0.0.0.0)
 * Running on http://127.0.0.1:5000
 * Running on http://172.31.128.41:5000 in _internal:224
[INFO] - 2023-03-29 13:32:22,599 : [33mPress CTRL+C to quit[0m in _internal:224
[INFO] - 2023-03-29 13:32:23,154 : 172.31.128.1 - - [29/Mar/2023 13:32:23] "GET / HTTP/1.1" 200 - in _internal:224
[INFO] - 2023-03-29 13:32:23,371 : 172.31.128.1 - - [29/Mar/2023 13:32:23] "[36mGET / HTTP/1.1[0m" 304 - in _internal:224
[INFO] - 2023-03-29 13:32:24,508 : 172.31.128.1 - - [29/Mar/2023 13:32:24] "GET /summary HTTP/1.1" 200 - in _internal:224
[INFO] - 2023-03-29 13:32:24,729 : 172.31.128.1 - - [29/Mar/2023 13:32:24] "GET /new HTTP/1.1" 200 - in _internal:224
[INFO] - 2023-03-29 13:32:24,797 : Serve Dutch Data in covid:50
[INFO] - 2023-03-29 13:32:25,168 : 172.31.128.1 - - [29/Mar/2023 13:32:25] "GET /netherlands HTTP/1.1" 200 - in _internal:224
[INFO] - 2023-03-29 13:32:25,741 : 172.31.128.1 - - [29/Mar/2023 13:32:25] "GET / HTTP/1.1" 200 - in _internal:224
[ERROR] - 2023-03-29 13:32:25,977 : An error has occurred: HTTP status 429 in covid:32
[ERROR] - 2023-03-29 13:32:25,979 : Exception on /summary [GET] in app:1741
Traceback (most recent call last):
  File "/home/runner/Dashboard-test-git/venv/lib/python3.10/site-packages/flask/app.py", line 2525, in wsgi_app
    response = self.full_dispatch_request()
  File "/home/runner/Dashboard-test-git/venv/lib/python3.10/site-packages/flask/app.py", line 1822, in full_dispatch_request
    rv = self.handle_user_exception(e)
  File "/home/runner/Dashboard-test-git/venv/lib/python3.10/site-packages/flask/app.py", line 1820, in full_dispatch_request
    rv = self.dispatch_request()
  File "/home/runner/Dashboard-test-git/venv/lib/python3.10/site-packages/flask/app.py", line 1796, in dispatch_request
    return self.ensure_sync(self.view_functions[rule.endpoint])(**view_args)
  File "main.py", line 36, in serve_summary
    json_template["data"]["values"] = json_data["Countries"]
KeyError: 'Countries'
[INFO] - 2023-03-29 13:32:25,985 : 172.31.128.1 - - [29/Mar/2023 13:32:25] "[35m[1mGET /summary HTTP/1.1[0m" 500 - in _internal:224
[ERROR] - 2023-03-29 13:32:25,995 : An error has occurred: HTTP status 429 in covid:32
[ERROR] - 2023-03-29 13:32:25,996 : Exception on /new [GET] in app:1741
Traceback (most recent call last):
  File "/home/runner/Dashboard-test-git/venv/lib/python3.10/site-packages/flask/app.py", line 2525, in wsgi_app
    response = self.full_dispatch_request()
  File "/home/runner/Dashboard-test-git/venv/lib/python3.10/site-packages/flask/app.py", line 1822, in full_dispatch_request
    rv = self.handle_user_exception(e)
  File "/home/runner/Dashboard-test-git/venv/lib/python3.10/site-packages/flask/app.py", line 1820, in full_dispatch_request
    rv = self.dispatch_request()
  File "/home/runner/Dashboard-test-git/venv/lib/python3.10/site-packages/flask/app.py", line 1796, in dispatch_request
    return self.ensure_sync(self.view_functions[rule.endpoint])(**view_args)
  File "main.py", line 54, in serve_summary_new
    for key in json_data["Global"]:
KeyError: 'Global'
[INFO] - 2023-03-29 13:32:26,002 : 172.31.128.1 - - [29/Mar/2023 13:32:26] "[35m[1mGET /new HTTP/1.1[0m" 500 - in _internal:224
[ERROR] - 2023-03-29 13:32:26,172 : An error has occurred: HTTP status 429 in covid:55
[ERROR] - 2023-03-29 13:32:26,184 : Exception on /netherlands [GET] in app:1741
Traceback (most recent call last):
  File "/home/runner/Dashboard-test-git/venv/lib/python3.10/site-packages/flask/app.py", line 2525, in wsgi_app
    response = self.full_dispatch_request()
  File "/home/runner/Dashboard-test-git/venv/lib/python3.10/site-packages/flask/app.py", line 1822, in full_dispatch_request
    rv = self.handle_user_exception(e)
  File "/home/runner/Dashboard-test-git/venv/lib/python3.10/site-packages/flask/app.py", line 1820, in full_dispatch_request
    rv = self.dispatch_request()
  File "/home/runner/Dashboard-test-git/venv/lib/python3.10/site-packages/flask/app.py", line 1796, in dispatch_request
    return self.ensure_sync(self.view_functions[rule.endpoint])(**view_args)
  File "main.py", line 77, in serve_netherlands_history
    json_template["data"]["values"] = json_data["data"]
KeyError: 'data'
[INFO] - 2023-03-29 13:32:26,185 : 172.31.128.1 - - [29/Mar/2023 13:32:26] "[35m[1mGET /netherlands HTTP/1.1[0m" 500 - in _internal:224
[ERROR] - 2023-03-29 13:32:26,808 : An error has occurred: HTTP status 429 in covid:32
[ERROR] - 2023-03-29 13:32:26,810 : Exception on /new [GET] in app:1741
Traceback (most recent call last):
  File "/home/runner/Dashboard-test-git/venv/lib/python3.10/site-packages/flask/app.py", line 2525, in wsgi_app
    response = self.full_dispatch_request()
  File "/home/runner/Dashboard-test-git/venv/lib/python3.10/site-packages/flask/app.py", line 1822, in full_dispatch_request
    rv = self.handle_user_exception(e)
  File "/home/runner/Dashboard-test-git/venv/lib/python3.10/site-packages/flask/app.py", line 1820, in full_dispatch_request
    rv = self.dispatch_request()
  File "/home/runner/Dashboard-test-git/venv/lib/python3.10/site-packages/flask/app.py", line 1796, in dispatch_request
    return self.ensure_sync(self.view_functions[rule.endpoint])(**view_args)
  File "main.py", line 54, in serve_summary_new
    for key in json_data["Global"]:
KeyError: 'Global'
[INFO] - 2023-03-29 13:32:26,817 : 172.31.128.1 - - [29/Mar/2023 13:32:26] "[35m[1mGET /new HTTP/1.1[0m" 500 - in _internal:224
[ERROR] - 2023-03-29 13:32:26,883 : An error has occurred: HTTP status 429 in covid:32
[ERROR] - 2023-03-29 13:32:26,893 : Exception on /summary [GET] in app:1741
Traceback (most recent call last):
  File "/home/runner/Dashboard-test-git/venv/lib/python3.10/site-packages/flask/app.py", line 2525, in wsgi_app
    response = self.full_dispatch_request()
  File "/home/runner/Dashboard-test-git/venv/lib/python3.10/site-packages/flask/app.py", line 1822, in full_dispatch_request
    rv = self.handle_user_exception(e)
  File "/home/runner/Dashboard-test-git/venv/lib/python3.10/site-packages/flask/app.py", line 1820, in full_dispatch_request
    rv = self.dispatch_request()
  File "/home/runner/Dashboard-test-git/venv/lib/python3.10/site-packages/flask/app.py", line 1796, in dispatch_request
    return self.ensure_sync(self.view_functions[rule.endpoint])(**view_args)
  File "main.py", line 36, in serve_summary
    json_template["data"]["values"] = json_data["Countries"]
KeyError: 'Countries'
[ERROR] - 2023-03-29 13:32:26,892 : An error has occurred: HTTP status 429 in covid:55
[INFO] - 2023-03-29 13:32:26,894 : 172.31.128.1 - - [29/Mar/2023 13:32:26] "[35m[1mGET /summary HTTP/1.1[0m" 500 - in _internal:224
[ERROR] - 2023-03-29 13:32:26,896 : Exception on /netherlands [GET] in app:1741
Traceback (most recent call last):
  File "/home/runner/Dashboard-test-git/venv/lib/python3.10/site-packages/flask/app.py", line 2525, in wsgi_app
    response = self.full_dispatch_request()
  File "/home/runner/Dashboard-test-git/venv/lib/python3.10/site-packages/flask/app.py", line 1822, in full_dispatch_request
    rv = self.handle_user_exception(e)
  File "/home/runner/Dashboard-test-git/venv/lib/python3.10/site-packages/flask/app.py", line 1820, in full_dispatch_request
    rv = self.dispatch_request()
  File "/home/runner/Dashboard-test-git/venv/lib/python3.10/site-packages/flask/app.py", line 1796, in dispatch_request
    return self.ensure_sync(self.view_functions[rule.endpoint])(**view_args)
  File "main.py", line 77, in serve_netherlands_history
    json_template["data"]["values"] = json_data["data"]
KeyError: 'data'
[INFO] - 2023-03-29 13:32:26,898 : 172.31.128.1 - - [29/Mar/2023 13:32:26] "[35m[1mGET /netherlands HTTP/1.1[0m" 500 - in _internal:224
[INFO] - 2023-03-29 13:32:48,190 : [31m[1mWARNING: This is a development server. Do not use it in a production deployment. Use a production WSGI server instead.[0m
 * Running on all addresses (0.0.0.0)
 * Running on http://127.0.0.1:5000
 * Running on http://172.31.128.41:5000 in _internal:224
[INFO] - 2023-03-29 13:32:48,190 : [33mPress CTRL+C to quit[0m in _internal:224
[INFO] - 2023-03-29 13:32:48,802 : 172.31.128.1 - - [29/Mar/2023 13:32:48] "GET / HTTP/1.1" 200 - in _internal:224
[INFO] - 2023-03-29 13:32:49,287 : 172.31.128.1 - - [29/Mar/2023 13:32:49] "[36mGET / HTTP/1.1[0m" 304 - in _internal:224
[INFO] - 2023-03-29 13:32:50,178 : 172.31.128.1 - - [29/Mar/2023 13:32:50] "GET /new HTTP/1.1" 200 - in _internal:224
[INFO] - 2023-03-29 13:32:50,188 : 172.31.128.1 - - [29/Mar/2023 13:32:50] "GET /summary HTTP/1.1" 200 - in _internal:224
[INFO] - 2023-03-29 13:32:50,383 : Serve Dutch Data in covid:50
[INFO] - 2023-03-29 13:32:50,690 : 172.31.128.1 - - [29/Mar/2023 13:32:50] "GET /netherlands HTTP/1.1" 200 - in _internal:224
[ERROR] - 2023-03-29 13:32:51,387 : An error has occurred: HTTP status 429 in covid:32
[ERROR] - 2023-03-29 13:32:51,388 : Exception on /new [GET] in app:1741
Traceback (most recent call last):
  File "/home/runner/Dashboard-test-git/venv/lib/python3.10/site-packages/flask/app.py", line 2525, in wsgi_app
    response = self.full_dispatch_request()
  File "/home/runner/Dashboard-test-git/venv/lib/python3.10/site-packages/flask/app.py", line 1822, in full_dispatch_request
    rv = self.handle_user_exception(e)
  File "/home/runner/Dashboard-test-git/venv/lib/python3.10/site-packages/flask/app.py", line 1820, in full_dispatch_request
    rv = self.dispatch_request()
  File "/home/runner/Dashboard-test-git/venv/lib/python3.10/site-packages/flask/app.py", line 1796, in dispatch_request
    return self.ensure_sync(self.view_functions[rule.endpoint])(**view_args)
  File "main.py", line 54, in serve_summary_new
    for key in json_data["Global"]:
KeyError: 'Global'
[INFO] - 2023-03-29 13:32:51,396 : 172.31.128.1 - - [29/Mar/2023 13:32:51] "[35m[1mGET /new HTTP/1.1[0m" 500 - in _internal:224
[ERROR] - 2023-03-29 13:32:51,563 : An error has occurred: HTTP status 429 in covid:32
[ERROR] - 2023-03-29 13:32:51,564 : Exception on /summary [GET] in app:1741
Traceback (most recent call last):
  File "/home/runner/Dashboard-test-git/venv/lib/python3.10/site-packages/flask/app.py", line 2525, in wsgi_app
    response = self.full_dispatch_request()
  File "/home/runner/Dashboard-test-git/venv/lib/python3.10/site-packages/flask/app.py", line 1822, in full_dispatch_request
    rv = self.handle_user_exception(e)
  File "/home/runner/Dashboard-test-git/venv/lib/python3.10/site-packages/flask/app.py", line 1820, in full_dispatch_request
    rv = self.dispatch_request()
  File "/home/runner/Dashboard-test-git/venv/lib/python3.10/site-packages/flask/app.py", line 1796, in dispatch_request
    return self.ensure_sync(self.view_functions[rule.endpoint])(**view_args)
  File "main.py", line 36, in serve_summary
    json_template["data"]["values"] = json_data["Countries"]
KeyError: 'Countries'
[INFO] - 2023-03-29 13:32:51,566 : 172.31.128.1 - - [29/Mar/2023 13:32:51] "[35m[1mGET /summary HTTP/1.1[0m" 500 - in _internal:224
[ERROR] - 2023-03-29 13:32:51,592 : An error has occurred: HTTP status 429 in covid:55
[ERROR] - 2023-03-29 13:32:51,593 : Exception on /netherlands [GET] in app:1741
Traceback (most recent call last):
  File "/home/runner/Dashboard-test-git/venv/lib/python3.10/site-packages/flask/app.py", line 2525, in wsgi_app
    response = self.full_dispatch_request()
  File "/home/runner/Dashboard-test-git/venv/lib/python3.10/site-packages/flask/app.py", line 1822, in full_dispatch_request
    rv = self.handle_user_exception(e)
  File "/home/runner/Dashboard-test-git/venv/lib/python3.10/site-packages/flask/app.py", line 1820, in full_dispatch_request
    rv = self.dispatch_request()
  File "/home/runner/Dashboard-test-git/venv/lib/python3.10/site-packages/flask/app.py", line 1796, in dispatch_request
    return self.ensure_sync(self.view_functions[rule.endpoint])(**view_args)
  File "main.py", line 77, in serve_netherlands_history
    json_template["data"]["values"] = json_data["data"]
KeyError: 'data'
[INFO] - 2023-03-29 13:32:51,595 : 172.31.128.1 - - [29/Mar/2023 13:32:51] "[35m[1mGET /netherlands HTTP/1.1[0m" 500 - in _internal:224
[ERROR] - 2023-03-29 13:32:52,173 : An error has occurred: HTTP status 429 in covid:32
[ERROR] - 2023-03-29 13:32:52,174 : Exception on /new [GET] in app:1741
Traceback (most recent call last):
  File "/home/runner/Dashboard-test-git/venv/lib/python3.10/site-packages/flask/app.py", line 2525, in wsgi_app
    response = self.full_dispatch_request()
  File "/home/runner/Dashboard-test-git/venv/lib/python3.10/site-packages/flask/app.py", line 1822, in full_dispatch_request
    rv = self.handle_user_exception(e)
  File "/home/runner/Dashboard-test-git/venv/lib/python3.10/site-packages/flask/app.py", line 1820, in full_dispatch_request
    rv = self.dispatch_request()
  File "/home/runner/Dashboard-test-git/venv/lib/python3.10/site-packages/flask/app.py", line 1796, in dispatch_request
    return self.ensure_sync(self.view_functions[rule.endpoint])(**view_args)
  File "main.py", line 54, in serve_summary_new
    for key in json_data["Global"]:
KeyError: 'Global'
[INFO] - 2023-03-29 13:32:52,176 : 172.31.128.1 - - [29/Mar/2023 13:32:52] "[35m[1mGET /new HTTP/1.1[0m" 500 - in _internal:224
[ERROR] - 2023-03-29 13:32:52,937 : An error has occurred: HTTP status 429 in covid:32
[ERROR] - 2023-03-29 13:32:52,938 : Exception on /new [GET] in app:1741
Traceback (most recent call last):
  File "/home/runner/Dashboard-test-git/venv/lib/python3.10/site-packages/flask/app.py", line 2525, in wsgi_app
    response = self.full_dispatch_request()
  File "/home/runner/Dashboard-test-git/venv/lib/python3.10/site-packages/flask/app.py", line 1822, in full_dispatch_request
    rv = self.handle_user_exception(e)
  File "/home/runner/Dashboard-test-git/venv/lib/python3.10/site-packages/flask/app.py", line 1820, in full_dispatch_request
    rv = self.dispatch_request()
  File "/home/runner/Dashboard-test-git/venv/lib/python3.10/site-packages/flask/app.py", line 1796, in dispatch_request
    return self.ensure_sync(self.view_functions[rule.endpoint])(**view_args)
  File "main.py", line 54, in serve_summary_new
    for key in json_data["Global"]:
KeyError: 'Global'
[INFO] - 2023-03-29 13:32:52,939 : 172.31.128.1 - - [29/Mar/2023 13:32:52] "[35m[1mGET /new HTTP/1.1[0m" 500 - in _internal:224
[INFO] - 2023-03-29 13:32:53,469 : 172.31.128.1 - - [29/Mar/2023 13:32:53] "GET / HTTP/1.1" 200 - in _internal:224
[ERROR] - 2023-03-29 13:32:54,489 : An error has occurred: HTTP status 429 in covid:55
[ERROR] - 2023-03-29 13:32:54,492 : Exception on /netherlands [GET] in app:1741
Traceback (most recent call last):
  File "/home/runner/Dashboard-test-git/venv/lib/python3.10/site-packages/flask/app.py", line 2525, in wsgi_app
    response = self.full_dispatch_request()
  File "/home/runner/Dashboard-test-git/venv/lib/python3.10/site-packages/flask/app.py", line 1822, in full_dispatch_request
    rv = self.handle_user_exception(e)
  File "/home/runner/Dashboard-test-git/venv/lib/python3.10/site-packages/flask/app.py", line 1820, in full_dispatch_request
    rv = self.dispatch_request()
  File "/home/runner/Dashboard-test-git/venv/lib/python3.10/site-packages/flask/app.py", line 1796, in dispatch_request
    return self.ensure_sync(self.view_functions[rule.endpoint])(**view_args)
  File "main.py", line 77, in serve_netherlands_history
    json_template["data"]["values"] = json_data["data"]
KeyError: 'data'
[INFO] - 2023-03-29 13:32:54,496 : 172.31.128.1 - - [29/Mar/2023 13:32:54] "[35m[1mGET /netherlands HTTP/1.1[0m" 500 - in _internal:224
[ERROR] - 2023-03-29 13:32:54,584 : An error has occurred: HTTP status 429 in covid:32
[ERROR] - 2023-03-29 13:32:54,585 : Exception on /summary [GET] in app:1741
Traceback (most recent call last):
  File "/home/runner/Dashboard-test-git/venv/lib/python3.10/site-packages/flask/app.py", line 2525, in wsgi_app
    response = self.full_dispatch_request()
  File "/home/runner/Dashboard-test-git/venv/lib/python3.10/site-packages/flask/app.py", line 1822, in full_dispatch_request
    rv = self.handle_user_exception(e)
  File "/home/runner/Dashboard-test-git/venv/lib/python3.10/site-packages/flask/app.py", line 1820, in full_dispatch_request
    rv = self.dispatch_request()
  File "/home/runner/Dashboard-test-git/venv/lib/python3.10/site-packages/flask/app.py", line 1796, in dispatch_request
    return self.ensure_sync(self.view_functions[rule.endpoint])(**view_args)
  File "main.py", line 36, in serve_summary
    json_template["data"]["values"] = json_data["Countries"]
KeyError: 'Countries'
[INFO] - 2023-03-29 13:32:54,587 : 172.31.128.1 - - [29/Mar/2023 13:32:54] "[35m[1mGET /summary HTTP/1.1[0m" 500 - in _internal:224
[ERROR] - 2023-03-29 13:32:54,601 : An error has occurred: HTTP status 429 in covid:32
[ERROR] - 2023-03-29 13:32:54,602 : Exception on /new [GET] in app:1741
Traceback (most recent call last):
  File "/home/runner/Dashboard-test-git/venv/lib/python3.10/site-packages/flask/app.py", line 2525, in wsgi_app
    response = self.full_dispatch_request()
  File "/home/runner/Dashboard-test-git/venv/lib/python3.10/site-packages/flask/app.py", line 1822, in full_dispatch_request
    rv = self.handle_user_exception(e)
  File "/home/runner/Dashboard-test-git/venv/lib/python3.10/site-packages/flask/app.py", line 1820, in full_dispatch_request
    rv = self.dispatch_request()
  File "/home/runner/Dashboard-test-git/venv/lib/python3.10/site-packages/flask/app.py", line 1796, in dispatch_request
    return self.ensure_sync(self.view_functions[rule.endpoint])(**view_args)
  File "main.py", line 54, in serve_summary_new
    for key in json_data["Global"]:
KeyError: 'Global'
[INFO] - 2023-03-29 13:32:54,604 : 172.31.128.1 - - [29/Mar/2023 13:32:54] "[35m[1mGET /new HTTP/1.1[0m" 500 - in _internal:224
[INFO] - 2023-03-29 13:32:55,492 : 172.31.128.1 - - [29/Mar/2023 13:32:55] "GET /new HTTP/1.1" 200 - in _internal:224
[INFO] - 2023-03-29 13:34:22,392 : [31m[1mWARNING: This is a development server. Do not use it in a production deployment. Use a production WSGI server instead.[0m
 * Running on all addresses (0.0.0.0)
 * Running on http://127.0.0.1:5000
 * Running on http://172.31.128.41:5000 in _internal:224
[INFO] - 2023-03-29 13:34:22,392 : [33mPress CTRL+C to quit[0m in _internal:224
[INFO] - 2023-03-29 13:34:23,157 : 172.31.128.1 - - [29/Mar/2023 13:34:23] "GET / HTTP/1.1" 200 - in _internal:224
[INFO] - 2023-03-29 13:34:23,546 : 172.31.128.1 - - [29/Mar/2023 13:34:23] "[36mGET / HTTP/1.1[0m" 304 - in _internal:224
[INFO] - 2023-03-29 13:34:24,763 : 172.31.128.1 - - [29/Mar/2023 13:34:24] "GET /new HTTP/1.1" 200 - in _internal:224
[INFO] - 2023-03-29 13:34:24,876 : 172.31.128.1 - - [29/Mar/2023 13:34:24] "GET /summary HTTP/1.1" 200 - in _internal:224
[INFO] - 2023-03-29 13:34:24,881 : Serve Dutch Data in covid:50
[INFO] - 2023-03-29 13:34:25,177 : 172.31.128.1 - - [29/Mar/2023 13:34:25] "GET /netherlands HTTP/1.1" 200 - in _internal:224
[ERROR] - 2023-03-29 13:34:25,795 : An error has occurred: HTTP status 429 in covid:32
[ERROR] - 2023-03-29 13:34:25,796 : Exception on /summary [GET] in app:1741
Traceback (most recent call last):
  File "/home/runner/Dashboard-test-git/venv/lib/python3.10/site-packages/flask/app.py", line 2525, in wsgi_app
    response = self.full_dispatch_request()
  File "/home/runner/Dashboard-test-git/venv/lib/python3.10/site-packages/flask/app.py", line 1822, in full_dispatch_request
    rv = self.handle_user_exception(e)
  File "/home/runner/Dashboard-test-git/venv/lib/python3.10/site-packages/flask/app.py", line 1820, in full_dispatch_request
    rv = self.dispatch_request()
  File "/home/runner/Dashboard-test-git/venv/lib/python3.10/site-packages/flask/app.py", line 1796, in dispatch_request
    return self.ensure_sync(self.view_functions[rule.endpoint])(**view_args)
  File "main.py", line 36, in serve_summary
    json_template["data"]["values"] = json_data["Countries"]
KeyError: 'Countries'
[INFO] - 2023-03-29 13:34:25,801 : 172.31.128.1 - - [29/Mar/2023 13:34:25] "[35m[1mGET /summary HTTP/1.1[0m" 500 - in _internal:224
[ERROR] - 2023-03-29 13:34:25,807 : An error has occurred: HTTP status 429 in covid:32
[ERROR] - 2023-03-29 13:34:25,808 : Exception on /new [GET] in app:1741
Traceback (most recent call last):
  File "/home/runner/Dashboard-test-git/venv/lib/python3.10/site-packages/flask/app.py", line 2525, in wsgi_app
    response = self.full_dispatch_request()
  File "/home/runner/Dashboard-test-git/venv/lib/python3.10/site-packages/flask/app.py", line 1822, in full_dispatch_request
    rv = self.handle_user_exception(e)
  File "/home/runner/Dashboard-test-git/venv/lib/python3.10/site-packages/flask/app.py", line 1820, in full_dispatch_request
    rv = self.dispatch_request()
  File "/home/runner/Dashboard-test-git/venv/lib/python3.10/site-packages/flask/app.py", line 1796, in dispatch_request
    return self.ensure_sync(self.view_functions[rule.endpoint])(**view_args)
  File "main.py", line 54, in serve_summary_new
    for key in json_data["Global"]:
KeyError: 'Global'
[INFO] - 2023-03-29 13:34:25,809 : 172.31.128.1 - - [29/Mar/2023 13:34:25] "[35m[1mGET /new HTTP/1.1[0m" 500 - in _internal:224
[ERROR] - 2023-03-29 13:34:26,010 : An error has occurred: HTTP status 429 in covid:55
[ERROR] - 2023-03-29 13:34:26,012 : Exception on /netherlands [GET] in app:1741
Traceback (most recent call last):
  File "/home/runner/Dashboard-test-git/venv/lib/python3.10/site-packages/flask/app.py", line 2525, in wsgi_app
    response = self.full_dispatch_request()
  File "/home/runner/Dashboard-test-git/venv/lib/python3.10/site-packages/flask/app.py", line 1822, in full_dispatch_request
    rv = self.handle_user_exception(e)
  File "/home/runner/Dashboard-test-git/venv/lib/python3.10/site-packages/flask/app.py", line 1820, in full_dispatch_request
    rv = self.dispatch_request()
  File "/home/runner/Dashboard-test-git/venv/lib/python3.10/site-packages/flask/app.py", line 1796, in dispatch_request
    return self.ensure_sync(self.view_functions[rule.endpoint])(**view_args)
  File "main.py", line 77, in serve_netherlands_history
    json_template["data"]["values"] = json_data["data"]
KeyError: 'data'
[INFO] - 2023-03-29 13:34:26,014 : 172.31.128.1 - - [29/Mar/2023 13:34:26] "[35m[1mGET /netherlands HTTP/1.1[0m" 500 - in _internal:224
[INFO] - 2023-03-29 13:34:57,386 : [31m[1mWARNING: This is a development server. Do not use it in a production deployment. Use a production WSGI server instead.[0m
 * Running on all addresses (0.0.0.0)
 * Running on http://127.0.0.1:5000
 * Running on http://172.31.128.41:5000 in _internal:224
[INFO] - 2023-03-29 13:34:57,387 : [33mPress CTRL+C to quit[0m in _internal:224
[INFO] - 2023-03-29 13:34:57,969 : 172.31.128.1 - - [29/Mar/2023 13:34:57] "[36mGET / HTTP/1.1[0m" 304 - in _internal:224
[INFO] - 2023-03-29 13:34:58,182 : 172.31.128.1 - - [29/Mar/2023 13:34:58] "[36mGET / HTTP/1.1[0m" 304 - in _internal:224
[INFO] - 2023-03-29 13:34:59,300 : 172.31.128.1 - - [29/Mar/2023 13:34:59] "GET /summary HTTP/1.1" 200 - in _internal:224
[INFO] - 2023-03-29 13:34:59,474 : Serve Dutch Data in covid:50
[INFO] - 2023-03-29 13:34:59,686 : 172.31.128.1 - - [29/Mar/2023 13:34:59] "GET /new HTTP/1.1" 200 - in _internal:224
[INFO] - 2023-03-29 13:34:59,702 : 172.31.128.1 - - [29/Mar/2023 13:34:59] "GET /netherlands HTTP/1.1" 200 - in _internal:224
[ERROR] - 2023-03-29 13:35:00,490 : An error has occurred: HTTP status 429 in covid:32
[ERROR] - 2023-03-29 13:35:00,493 : Exception on /summary [GET] in app:1741
Traceback (most recent call last):
  File "/home/runner/Dashboard-test-git/venv/lib/python3.10/site-packages/flask/app.py", line 2525, in wsgi_app
    response = self.full_dispatch_request()
  File "/home/runner/Dashboard-test-git/venv/lib/python3.10/site-packages/flask/app.py", line 1822, in full_dispatch_request
    rv = self.handle_user_exception(e)
  File "/home/runner/Dashboard-test-git/venv/lib/python3.10/site-packages/flask/app.py", line 1820, in full_dispatch_request
    rv = self.dispatch_request()
  File "/home/runner/Dashboard-test-git/venv/lib/python3.10/site-packages/flask/app.py", line 1796, in dispatch_request
    return self.ensure_sync(self.view_functions[rule.endpoint])(**view_args)
  File "main.py", line 36, in serve_summary
    json_template["data"]["values"] = json_data["Countries"]
KeyError: 'Countries'
[INFO] - 2023-03-29 13:35:00,496 : 172.31.128.1 - - [29/Mar/2023 13:35:00] "[35m[1mGET /summary HTTP/1.1[0m" 500 - in _internal:224
[ERROR] - 2023-03-29 13:35:00,687 : An error has occurred: HTTP status 429 in covid:32
[ERROR] - 2023-03-29 13:35:00,688 : Exception on /new [GET] in app:1741
Traceback (most recent call last):
  File "/home/runner/Dashboard-test-git/venv/lib/python3.10/site-packages/flask/app.py", line 2525, in wsgi_app
    response = self.full_dispatch_request()
  File "/home/runner/Dashboard-test-git/venv/lib/python3.10/site-packages/flask/app.py", line 1822, in full_dispatch_request
    rv = self.handle_user_exception(e)
  File "/home/runner/Dashboard-test-git/venv/lib/python3.10/site-packages/flask/app.py", line 1820, in full_dispatch_request
    rv = self.dispatch_request()
  File "/home/runner/Dashboard-test-git/venv/lib/python3.10/site-packages/flask/app.py", line 1796, in dispatch_request
    return self.ensure_sync(self.view_functions[rule.endpoint])(**view_args)
  File "main.py", line 54, in serve_summary_new
    for key in json_data["Global"]:
KeyError: 'Global'
[INFO] - 2023-03-29 13:35:00,689 : 172.31.128.1 - - [29/Mar/2023 13:35:00] "[35m[1mGET /new HTTP/1.1[0m" 500 - in _internal:224
[ERROR] - 2023-03-29 13:35:00,694 : An error has occurred: HTTP status 429 in covid:55
[ERROR] - 2023-03-29 13:35:00,698 : Exception on /netherlands [GET] in app:1741
Traceback (most recent call last):
  File "/home/runner/Dashboard-test-git/venv/lib/python3.10/site-packages/flask/app.py", line 2525, in wsgi_app
    response = self.full_dispatch_request()
  File "/home/runner/Dashboard-test-git/venv/lib/python3.10/site-packages/flask/app.py", line 1822, in full_dispatch_request
    rv = self.handle_user_exception(e)
  File "/home/runner/Dashboard-test-git/venv/lib/python3.10/site-packages/flask/app.py", line 1820, in full_dispatch_request
    rv = self.dispatch_request()
  File "/home/runner/Dashboard-test-git/venv/lib/python3.10/site-packages/flask/app.py", line 1796, in dispatch_request
    return self.ensure_sync(self.view_functions[rule.endpoint])(**view_args)
  File "main.py", line 78, in serve_netherlands_history
    json_template["data"]["values"] = json_data["data"]
KeyError: 'data'
[INFO] - 2023-03-29 13:35:00,699 : 172.31.128.1 - - [29/Mar/2023 13:35:00] "[35m[1mGET /netherlands HTTP/1.1[0m" 500 - in _internal:224
[INFO] - 2023-03-29 13:35:00,832 : 172.31.128.1 - - [29/Mar/2023 13:35:00] "GET / HTTP/1.1" 200 - in _internal:224
[ERROR] - 2023-03-29 13:35:01,828 : An error has occurred: HTTP status 429 in covid:55
[ERROR] - 2023-03-29 13:35:01,829 : Exception on /netherlands [GET] in app:1741
Traceback (most recent call last):
  File "/home/runner/Dashboard-test-git/venv/lib/python3.10/site-packages/flask/app.py", line 2525, in wsgi_app
    response = self.full_dispatch_request()
  File "/home/runner/Dashboard-test-git/venv/lib/python3.10/site-packages/flask/app.py", line 1822, in full_dispatch_request
    rv = self.handle_user_exception(e)
  File "/home/runner/Dashboard-test-git/venv/lib/python3.10/site-packages/flask/app.py", line 1820, in full_dispatch_request
    rv = self.dispatch_request()
  File "/home/runner/Dashboard-test-git/venv/lib/python3.10/site-packages/flask/app.py", line 1796, in dispatch_request
    return self.ensure_sync(self.view_functions[rule.endpoint])(**view_args)
  File "main.py", line 78, in serve_netherlands_history
    json_template["data"]["values"] = json_data["data"]
KeyError: 'data'
[INFO] - 2023-03-29 13:35:01,830 : 172.31.128.1 - - [29/Mar/2023 13:35:01] "[35m[1mGET /netherlands HTTP/1.1[0m" 500 - in _internal:224
[ERROR] - 2023-03-29 13:35:01,880 : An error has occurred: HTTP status 429 in covid:32
[ERROR] - 2023-03-29 13:35:01,881 : Exception on /new [GET] in app:1741
Traceback (most recent call last):
  File "/home/runner/Dashboard-test-git/venv/lib/python3.10/site-packages/flask/app.py", line 2525, in wsgi_app
    response = self.full_dispatch_request()
  File "/home/runner/Dashboard-test-git/venv/lib/python3.10/site-packages/flask/app.py", line 1822, in full_dispatch_request
    rv = self.handle_user_exception(e)
  File "/home/runner/Dashboard-test-git/venv/lib/python3.10/site-packages/flask/app.py", line 1820, in full_dispatch_request
    rv = self.dispatch_request()
  File "/home/runner/Dashboard-test-git/venv/lib/python3.10/site-packages/flask/app.py", line 1796, in dispatch_request
    return self.ensure_sync(self.view_functions[rule.endpoint])(**view_args)
  File "main.py", line 54, in serve_summary_new
    for key in json_data["Global"]:
KeyError: 'Global'
[INFO] - 2023-03-29 13:35:01,883 : 172.31.128.1 - - [29/Mar/2023 13:35:01] "[35m[1mGET /new HTTP/1.1[0m" 500 - in _internal:224
[ERROR] - 2023-03-29 13:35:01,895 : An error has occurred: HTTP status 429 in covid:32
[ERROR] - 2023-03-29 13:35:01,896 : Exception on /summary [GET] in app:1741
Traceback (most recent call last):
  File "/home/runner/Dashboard-test-git/venv/lib/python3.10/site-packages/flask/app.py", line 2525, in wsgi_app
    response = self.full_dispatch_request()
  File "/home/runner/Dashboard-test-git/venv/lib/python3.10/site-packages/flask/app.py", line 1822, in full_dispatch_request
    rv = self.handle_user_exception(e)
  File "/home/runner/Dashboard-test-git/venv/lib/python3.10/site-packages/flask/app.py", line 1820, in full_dispatch_request
    rv = self.dispatch_request()
  File "/home/runner/Dashboard-test-git/venv/lib/python3.10/site-packages/flask/app.py", line 1796, in dispatch_request
    return self.ensure_sync(self.view_functions[rule.endpoint])(**view_args)
  File "main.py", line 36, in serve_summary
    json_template["data"]["values"] = json_data["Countries"]
KeyError: 'Countries'
[INFO] - 2023-03-29 13:35:01,907 : 172.31.128.1 - - [29/Mar/2023 13:35:01] "[35m[1mGET /summary HTTP/1.1[0m" 500 - in _internal:224
[INFO] - 2023-03-29 13:35:46,306 : [31m[1mWARNING: This is a development server. Do not use it in a production deployment. Use a production WSGI server instead.[0m
 * Running on all addresses (0.0.0.0)
 * Running on http://127.0.0.1:5000
 * Running on http://172.31.128.41:5000 in _internal:224
[INFO] - 2023-03-29 13:35:46,306 : [33mPress CTRL+C to quit[0m in _internal:224
[INFO] - 2023-03-29 13:35:46,517 : 172.31.128.1 - - [29/Mar/2023 13:35:46] "[33mOPTIONS * HTTP/1.1[0m" 404 - in _internal:224
[INFO] - 2023-03-29 13:35:46,618 : 172.31.128.1 - - [29/Mar/2023 13:35:46] "[36mGET / HTTP/1.1[0m" 304 - in _internal:224
[INFO] - 2023-03-29 13:35:46,925 : 172.31.128.1 - - [29/Mar/2023 13:35:46] "[36mGET / HTTP/1.1[0m" 304 - in _internal:224
[INFO] - 2023-03-29 13:35:47,640 : 172.31.128.1 - - [29/Mar/2023 13:35:47] "[36mGET / HTTP/1.1[0m" 304 - in _internal:224
[INFO] - 2023-03-29 13:35:47,985 : 172.31.128.1 - - [29/Mar/2023 13:35:47] "GET /summary HTTP/1.1" 200 - in _internal:224
[INFO] - 2023-03-29 13:35:48,070 : 172.31.128.1 - - [29/Mar/2023 13:35:48] "GET /new HTTP/1.1" 200 - in _internal:224
[INFO] - 2023-03-29 13:35:48,080 : Serve Dutch Data in covid:50
[INFO] - 2023-03-29 13:35:48,586 : 172.31.128.1 - - [29/Mar/2023 13:35:48] "GET /netherlands HTTP/1.1" 200 - in _internal:224
[ERROR] - 2023-03-29 13:35:48,779 : An error has occurred: HTTP status 429 in covid:32
[ERROR] - 2023-03-29 13:35:48,788 : Exception on /summary [GET] in app:1741
Traceback (most recent call last):
  File "/home/runner/Dashboard-test-git/venv/lib/python3.10/site-packages/flask/app.py", line 2525, in wsgi_app
    response = self.full_dispatch_request()
  File "/home/runner/Dashboard-test-git/venv/lib/python3.10/site-packages/flask/app.py", line 1822, in full_dispatch_request
    rv = self.handle_user_exception(e)
  File "/home/runner/Dashboard-test-git/venv/lib/python3.10/site-packages/flask/app.py", line 1820, in full_dispatch_request
    rv = self.dispatch_request()
  File "/home/runner/Dashboard-test-git/venv/lib/python3.10/site-packages/flask/app.py", line 1796, in dispatch_request
    return self.ensure_sync(self.view_functions[rule.endpoint])(**view_args)
  File "main.py", line 36, in serve_summary
    json_template["data"]["values"] = json_data["Countries"]
KeyError: 'Countries'
[ERROR] - 2023-03-29 13:35:48,788 : An error has occurred: HTTP status 429 in covid:32
[ERROR] - 2023-03-29 13:35:48,793 : Exception on /new [GET] in app:1741
Traceback (most recent call last):
  File "/home/runner/Dashboard-test-git/venv/lib/python3.10/site-packages/flask/app.py", line 2525, in wsgi_app
    response = self.full_dispatch_request()
  File "/home/runner/Dashboard-test-git/venv/lib/python3.10/site-packages/flask/app.py", line 1822, in full_dispatch_request
    rv = self.handle_user_exception(e)
  File "/home/runner/Dashboard-test-git/venv/lib/python3.10/site-packages/flask/app.py", line 1820, in full_dispatch_request
    rv = self.dispatch_request()
  File "/home/runner/Dashboard-test-git/venv/lib/python3.10/site-packages/flask/app.py", line 1796, in dispatch_request
    return self.ensure_sync(self.view_functions[rule.endpoint])(**view_args)
  File "main.py", line 54, in serve_summary_new
    for key in json_data["Global"]:
KeyError: 'Global'
[INFO] - 2023-03-29 13:35:48,792 : 172.31.128.1 - - [29/Mar/2023 13:35:48] "[35m[1mGET /summary HTTP/1.1[0m" 500 - in _internal:224
[INFO] - 2023-03-29 13:35:48,795 : 172.31.128.1 - - [29/Mar/2023 13:35:48] "[35m[1mGET /new HTTP/1.1[0m" 500 - in _internal:224
[ERROR] - 2023-03-29 13:35:48,799 : An error has occurred: HTTP status 429 in covid:55
[ERROR] - 2023-03-29 13:35:48,800 : Exception on /netherlands [GET] in app:1741
Traceback (most recent call last):
  File "/home/runner/Dashboard-test-git/venv/lib/python3.10/site-packages/flask/app.py", line 2525, in wsgi_app
    response = self.full_dispatch_request()
  File "/home/runner/Dashboard-test-git/venv/lib/python3.10/site-packages/flask/app.py", line 1822, in full_dispatch_request
    rv = self.handle_user_exception(e)
  File "/home/runner/Dashboard-test-git/venv/lib/python3.10/site-packages/flask/app.py", line 1820, in full_dispatch_request
    rv = self.dispatch_request()
  File "/home/runner/Dashboard-test-git/venv/lib/python3.10/site-packages/flask/app.py", line 1796, in dispatch_request
    return self.ensure_sync(self.view_functions[rule.endpoint])(**view_args)
  File "main.py", line 78, in serve_netherlands_history
    json_template["data"]["values"] = json_data["data"]
KeyError: 'data'
[INFO] - 2023-03-29 13:35:48,802 : 172.31.128.1 - - [29/Mar/2023 13:35:48] "[35m[1mGET /netherlands HTTP/1.1[0m" 500 - in _internal:224
[ERROR] - 2023-03-29 13:35:49,802 : An error has occurred: HTTP status 429 in covid:32
[ERROR] - 2023-03-29 13:35:49,804 : Exception on /new [GET] in app:1741
Traceback (most recent call last):
  File "/home/runner/Dashboard-test-git/venv/lib/python3.10/site-packages/flask/app.py", line 2525, in wsgi_app
    response = self.full_dispatch_request()
  File "/home/runner/Dashboard-test-git/venv/lib/python3.10/site-packages/flask/app.py", line 1822, in full_dispatch_request
    rv = self.handle_user_exception(e)
  File "/home/runner/Dashboard-test-git/venv/lib/python3.10/site-packages/flask/app.py", line 1820, in full_dispatch_request
    rv = self.dispatch_request()
  File "/home/runner/Dashboard-test-git/venv/lib/python3.10/site-packages/flask/app.py", line 1796, in dispatch_request
    return self.ensure_sync(self.view_functions[rule.endpoint])(**view_args)
  File "main.py", line 54, in serve_summary_new
    for key in json_data["Global"]:
KeyError: 'Global'
[INFO] - 2023-03-29 13:35:49,806 : 172.31.128.1 - - [29/Mar/2023 13:35:49] "[35m[1mGET /new HTTP/1.1[0m" 500 - in _internal:224
[ERROR] - 2023-03-29 13:35:49,870 : An error has occurred: HTTP status 429 in covid:32
[ERROR] - 2023-03-29 13:35:49,895 : Exception on /summary [GET] in app:1741
Traceback (most recent call last):
  File "/home/runner/Dashboard-test-git/venv/lib/python3.10/site-packages/flask/app.py", line 2525, in wsgi_app
    response = self.full_dispatch_request()
  File "/home/runner/Dashboard-test-git/venv/lib/python3.10/site-packages/flask/app.py", line 1822, in full_dispatch_request
    rv = self.handle_user_exception(e)
  File "/home/runner/Dashboard-test-git/venv/lib/python3.10/site-packages/flask/app.py", line 1820, in full_dispatch_request
    rv = self.dispatch_request()
  File "/home/runner/Dashboard-test-git/venv/lib/python3.10/site-packages/flask/app.py", line 1796, in dispatch_request
    return self.ensure_sync(self.view_functions[rule.endpoint])(**view_args)
  File "main.py", line 36, in serve_summary
    json_template["data"]["values"] = json_data["Countries"]
KeyError: 'Countries'
[INFO] - 2023-03-29 13:35:49,919 : 172.31.128.1 - - [29/Mar/2023 13:35:49] "[35m[1mGET /summary HTTP/1.1[0m" 500 - in _internal:224
[ERROR] - 2023-03-29 13:35:50,087 : An error has occurred: HTTP status 429 in covid:55
[ERROR] - 2023-03-29 13:35:50,088 : Exception on /netherlands [GET] in app:1741
Traceback (most recent call last):
  File "/home/runner/Dashboard-test-git/venv/lib/python3.10/site-packages/flask/app.py", line 2525, in wsgi_app
    response = self.full_dispatch_request()
  File "/home/runner/Dashboard-test-git/venv/lib/python3.10/site-packages/flask/app.py", line 1822, in full_dispatch_request
    rv = self.handle_user_exception(e)
  File "/home/runner/Dashboard-test-git/venv/lib/python3.10/site-packages/flask/app.py", line 1820, in full_dispatch_request
    rv = self.dispatch_request()
  File "/home/runner/Dashboard-test-git/venv/lib/python3.10/site-packages/flask/app.py", line 1796, in dispatch_request
    return self.ensure_sync(self.view_functions[rule.endpoint])(**view_args)
  File "main.py", line 78, in serve_netherlands_history
    json_template["data"]["values"] = json_data["data"]
KeyError: 'data'
[INFO] - 2023-03-29 13:35:50,090 : 172.31.128.1 - - [29/Mar/2023 13:35:50] "[35m[1mGET /netherlands HTTP/1.1[0m" 500 - in _internal:224
